Traceback (most recent call last):
  File "/home/lighvzkx/max_app/passenger_wsgi.py", line 1, in <module>
    from max_app_prooj.wsgi import application
  File "/home/lighvzkx/max_app/max_app_prooj/wsgi.py", line 12, in <module>
    from django.core.wsgi import get_wsgi_application
ModuleNotFoundError: No module named 'django'
Traceback (most recent call last):
  File "/home/lighvzkx/max_app/passenger_wsgi.py", line 1, in <module>
    from max_app_prooj.wsgi import application
  File "/home/lighvzkx/max_app/max_app_prooj/wsgi.py", line 12, in <module>
    from django.core.wsgi import get_wsgi_application
ModuleNotFoundError: No module named 'django'
Traceback (most recent call last):
  File "/home/lighvzkx/max_app/passenger_wsgi.py", line 1, in <module>
    from max_app_prooj.wsgi import application
  File "/home/lighvzkx/max_app/max_app_prooj/wsgi.py", line 12, in <module>
    from django.core.wsgi import get_wsgi_application
ModuleNotFoundError: No module named 'django'
Traceback (most recent call last):
  File "/home/lighvzkx/virtualenv/max_app/3.11/lib/python3.11/site-packages/django/db/backends/mysql/base.py", line 15, in <module>
    import MySQLdb as Database
ModuleNotFoundError: No module named 'MySQLdb'

The above exception was the direct cause of the following exception:

Traceback (most recent call last):
  File "/home/lighvzkx/max_app/passenger_wsgi.py", line 1, in <module>
    from max_app_prooj.wsgi import application
  File "/home/lighvzkx/max_app/max_app_prooj/wsgi.py", line 16, in <module>
    application = get_wsgi_application()
                  ^^^^^^^^^^^^^^^^^^^^^^
  File "/home/lighvzkx/virtualenv/max_app/3.11/lib/python3.11/site-packages/django/core/wsgi.py", line 12, in get_wsgi_application
    django.setup(set_prefix=False)
  File "/home/lighvzkx/virtualenv/max_app/3.11/lib/python3.11/site-packages/django/__init__.py", line 24, in setup
    apps.populate(settings.INSTALLED_APPS)
  File "/home/lighvzkx/virtualenv/max_app/3.11/lib/python3.11/site-packages/django/apps/registry.py", line 116, in populate
    app_config.import_models()
  File "/home/lighvzkx/virtualenv/max_app/3.11/lib/python3.11/site-packages/django/apps/config.py", line 269, in import_models
    self.models_module = import_module(models_module_name)
                         ^^^^^^^^^^^^^^^^^^^^^^^^^^^^^^^^^
  File "/opt/alt/python311/lib64/python3.11/importlib/__init__.py", line 126, in import_module
    return _bootstrap._gcd_import(name[level:], package, level)
           ^^^^^^^^^^^^^^^^^^^^^^^^^^^^^^^^^^^^^^^^^^^^^^^^^^^^
  File "/home/lighvzkx/virtualenv/max_app/3.11/lib/python3.11/site-packages/django/contrib/auth/models.py", line 3, in <module>
    from django.contrib.auth.base_user import AbstractBaseUser, BaseUserManager
  File "/home/lighvzkx/virtualenv/max_app/3.11/lib/python3.11/site-packages/django/contrib/auth/base_user.py", line 57, in <module>
    class AbstractBaseUser(models.Model):
  File "/home/lighvzkx/virtualenv/max_app/3.11/lib/python3.11/site-packages/django/db/models/base.py", line 143, in __new__
    new_class.add_to_class("_meta", Options(meta, app_label))
  File "/home/lighvzkx/virtualenv/max_app/3.11/lib/python3.11/site-packages/django/db/models/base.py", line 371, in add_to_class
    value.contribute_to_class(cls, name)
  File "/home/lighvzkx/virtualenv/max_app/3.11/lib/python3.11/site-packages/django/db/models/options.py", line 243, in contribute_to_class
    self.db_table, connection.ops.max_name_length()
                   ^^^^^^^^^^^^^^
  File "/home/lighvzkx/virtualenv/max_app/3.11/lib/python3.11/site-packages/django/utils/connection.py", line 15, in __getattr__
    return getattr(self._connections[self._alias], item)
                   ~~~~~~~~~~~~~~~~~^^^^^^^^^^^^^
  File "/home/lighvzkx/virtualenv/max_app/3.11/lib/python3.11/site-packages/django/utils/connection.py", line 62, in __getitem__
    conn = self.create_connection(alias)
           ^^^^^^^^^^^^^^^^^^^^^^^^^^^^^
  File "/home/lighvzkx/virtualenv/max_app/3.11/lib/python3.11/site-packages/django/db/utils.py", line 193, in create_connection
    backend = load_backend(db["ENGINE"])
              ^^^^^^^^^^^^^^^^^^^^^^^^^^
  File "/home/lighvzkx/virtualenv/max_app/3.11/lib/python3.11/site-packages/django/db/utils.py", line 113, in load_backend
    return import_module("%s.base" % backend_name)
           ^^^^^^^^^^^^^^^^^^^^^^^^^^^^^^^^^^^^^^^
  File "/opt/alt/python311/lib64/python3.11/importlib/__init__.py", line 126, in import_module
    return _bootstrap._gcd_import(name[level:], package, level)
           ^^^^^^^^^^^^^^^^^^^^^^^^^^^^^^^^^^^^^^^^^^^^^^^^^^^^
  File "/home/lighvzkx/virtualenv/max_app/3.11/lib/python3.11/site-packages/django/db/backends/mysql/base.py", line 17, in <module>
    raise ImproperlyConfigured(
django.core.exceptions.ImproperlyConfigured: Error loading MySQLdb module.
Did you install mysqlclient?
Traceback (most recent call last):
  File "/home/lighvzkx/max_app/passenger_wsgi.py", line 1, in <module>
    from max_app_prooj.wsgi import application
  File "/home/lighvzkx/max_app/max_app_prooj/wsgi.py", line 16, in <module>
    application = get_wsgi_application()
                  ^^^^^^^^^^^^^^^^^^^^^^
  File "/home/lighvzkx/virtualenv/max_app/3.11/lib/python3.11/site-packages/django/core/wsgi.py", line 12, in get_wsgi_application
    django.setup(set_prefix=False)
  File "/home/lighvzkx/virtualenv/max_app/3.11/lib/python3.11/site-packages/django/__init__.py", line 24, in setup
    apps.populate(settings.INSTALLED_APPS)
  File "/home/lighvzkx/virtualenv/max_app/3.11/lib/python3.11/site-packages/django/apps/registry.py", line 83, in populate
    raise RuntimeError("populate() isn't reentrant")
RuntimeError: populate() isn't reentrant
Traceback (most recent call last):
  File "/home/lighvzkx/max_app/passenger_wsgi.py", line 1, in <module>
    from max_app_prooj.wsgi import application
  File "/home/lighvzkx/max_app/max_app_prooj/wsgi.py", line 16, in <module>
    application = get_wsgi_application()
                  ^^^^^^^^^^^^^^^^^^^^^^
  File "/home/lighvzkx/virtualenv/max_app/3.11/lib/python3.11/site-packages/django/core/wsgi.py", line 12, in get_wsgi_application
    django.setup(set_prefix=False)
  File "/home/lighvzkx/virtualenv/max_app/3.11/lib/python3.11/site-packages/django/__init__.py", line 24, in setup
    apps.populate(settings.INSTALLED_APPS)
  File "/home/lighvzkx/virtualenv/max_app/3.11/lib/python3.11/site-packages/django/apps/registry.py", line 83, in populate
    raise RuntimeError("populate() isn't reentrant")
RuntimeError: populate() isn't reentrant
Not Found: /favicon.ico
Not Found: /favicon.ico
Forbidden (CSRF token from POST incorrect.): /admin/login/
Forbidden (CSRF token from POST incorrect.): /admin/login/
Not Found: /favicon.ico
Not Found: /favicon.ico
Not Found: /favicon.ico
[ERROR] [UID:13895][2358] wsgiAppHandler pApp->start_response() return NULL.
Traceback (most recent call last):
  File "/home/lighvzkx/virtualenv/max_app/3.11/lib/python3.11/site-packages/django/core/handlers/exception.py", line 55, in inner
    response = get_response(request)
               ^^^^^^^^^^^^^^^^^^^^^
  File "/home/lighvzkx/virtualenv/max_app/3.11/lib/python3.11/site-packages/django/core/handlers/base.py", line 181, in _get_response
    callback, callback_args, callback_kwargs = self.resolve_request(request)
                                               ^^^^^^^^^^^^^^^^^^^^^^^^^^^^^
  File "/home/lighvzkx/virtualenv/max_app/3.11/lib/python3.11/site-packages/django/core/handlers/base.py", line 313, in resolve_request
    resolver_match = resolver.resolve(request.path_info)
                     ^^^^^^^^^^^^^^^^^^^^^^^^^^^^^^^^^^^
  File "/home/lighvzkx/virtualenv/max_app/3.11/lib/python3.11/site-packages/django/urls/resolvers.py", line 663, in resolve
    for pattern in self.url_patterns:
                   ^^^^^^^^^^^^^^^^^
  File "/home/lighvzkx/virtualenv/max_app/3.11/lib/python3.11/site-packages/django/utils/functional.py", line 57, in __get__
    res = instance.__dict__[self.name] = self.func(instance)
                                         ^^^^^^^^^^^^^^^^^^^
  File "/home/lighvzkx/virtualenv/max_app/3.11/lib/python3.11/site-packages/django/urls/resolvers.py", line 715, in url_patterns
    patterns = getattr(self.urlconf_module, "urlpatterns", self.urlconf_module)
                       ^^^^^^^^^^^^^^^^^^^
  File "/home/lighvzkx/virtualenv/max_app/3.11/lib/python3.11/site-packages/django/utils/functional.py", line 57, in __get__
    res = instance.__dict__[self.name] = self.func(instance)
                                         ^^^^^^^^^^^^^^^^^^^
  File "/home/lighvzkx/virtualenv/max_app/3.11/lib/python3.11/site-packages/django/urls/resolvers.py", line 708, in urlconf_module
    return import_module(self.urlconf_name)
           ^^^^^^^^^^^^^^^^^^^^^^^^^^^^^^^^
  File "/opt/alt/python311/lib64/python3.11/importlib/__init__.py", line 126, in import_module
    return _bootstrap._gcd_import(name[level:], package, level)
           ^^^^^^^^^^^^^^^^^^^^^^^^^^^^^^^^^^^^^^^^^^^^^^^^^^^^
  File "<frozen importlib._bootstrap>", line 1204, in _gcd_import
  File "<frozen importlib._bootstrap>", line 1176, in _find_and_load
  File "<frozen importlib._bootstrap>", line 1147, in _find_and_load_unlocked
  File "<frozen importlib._bootstrap>", line 690, in _load_unlocked
  File "<frozen importlib._bootstrap_external>", line 940, in exec_module
  File "<frozen importlib._bootstrap>", line 241, in _call_with_frames_removed
  File "/home/lighvzkx/max_app/max_app_prooj/urls.py", line 22, in <module>
    path('', include('business.urls')),
             ^^^^^^^^^^^^^^^^^^^^^^^^
  File "/home/lighvzkx/virtualenv/max_app/3.11/lib/python3.11/site-packages/django/urls/conf.py", line 38, in include
    urlconf_module = import_module(urlconf_module)
                     ^^^^^^^^^^^^^^^^^^^^^^^^^^^^^
  File "/opt/alt/python311/lib64/python3.11/importlib/__init__.py", line 126, in import_module
    return _bootstrap._gcd_import(name[level:], package, level)
           ^^^^^^^^^^^^^^^^^^^^^^^^^^^^^^^^^^^^^^^^^^^^^^^^^^^^
  File "<frozen importlib._bootstrap>", line 1204, in _gcd_import
  File "<frozen importlib._bootstrap>", line 1176, in _find_and_load
  File "<frozen importlib._bootstrap>", line 1140, in _find_and_load_unlocked
ModuleNotFoundError: No module named 'business.urls'

During handling of the above exception, another exception occurred:

Traceback (most recent call last):
  File "/home/lighvzkx/virtualenv/max_app/3.11/lib/python3.11/site-packages/django/core/handlers/exception.py", line 55, in inner
    response = get_response(request)
               ^^^^^^^^^^^^^^^^^^^^^
  File "/home/lighvzkx/virtualenv/max_app/3.11/lib/python3.11/site-packages/django/utils/deprecation.py", line 134, in __call__
    response = response or self.get_response(request)
                           ^^^^^^^^^^^^^^^^^^^^^^^^^^
  File "/home/lighvzkx/virtualenv/max_app/3.11/lib/python3.11/site-packages/django/core/handlers/exception.py", line 57, in inner
    response = response_for_exception(request, exc)
               ^^^^^^^^^^^^^^^^^^^^^^^^^^^^^^^^^^^^
  File "/home/lighvzkx/virtualenv/max_app/3.11/lib/python3.11/site-packages/django/core/handlers/exception.py", line 140, in response_for_exception
    response = handle_uncaught_exception(
               ^^^^^^^^^^^^^^^^^^^^^^^^^^
  File "/home/lighvzkx/virtualenv/max_app/3.11/lib/python3.11/site-packages/django/core/handlers/exception.py", line 181, in handle_uncaught_exception
    return debug.technical_500_response(request, *exc_info)
           ^^^^^^^^^^^^^^^^^^^^^^^^^^^^^^^^^^^^^^^^^^^^^^^^
  File "/home/lighvzkx/virtualenv/max_app/3.11/lib/python3.11/site-packages/django/views/debug.py", line 67, in technical_500_response
    html = reporter.get_traceback_html()
           ^^^^^^^^^^^^^^^^^^^^^^^^^^^^^
  File "/home/lighvzkx/virtualenv/max_app/3.11/lib/python3.11/site-packages/django/views/debug.py", line 410, in get_traceback_html
    c = Context(self.get_traceback_data(), use_l10n=False)
                ^^^^^^^^^^^^^^^^^^^^^^^^^
  File "/home/lighvzkx/virtualenv/max_app/3.11/lib/python3.11/site-packages/django/views/debug.py", line 393, in get_traceback_data
    c["raising_view_name"] = get_caller(self.request)
                             ^^^^^^^^^^^^^^^^^^^^^^^^
  File "/home/lighvzkx/virtualenv/max_app/3.11/lib/python3.11/site-packages/django/views/debug.py", line 100, in get_caller
    resolver_match = resolve(request.path)
                     ^^^^^^^^^^^^^^^^^^^^^
  File "/home/lighvzkx/virtualenv/max_app/3.11/lib/python3.11/site-packages/django/urls/base.py", line 24, in resolve
    return get_resolver(urlconf).resolve(path)
           ^^^^^^^^^^^^^^^^^^^^^^^^^^^^^^^^^^^
  File "/home/lighvzkx/virtualenv/max_app/3.11/lib/python3.11/site-packages/django/urls/resolvers.py", line 663, in resolve
    for pattern in self.url_patterns:
                   ^^^^^^^^^^^^^^^^^
  File "/home/lighvzkx/virtualenv/max_app/3.11/lib/python3.11/site-packages/django/utils/functional.py", line 57, in __get__
    res = instance.__dict__[self.name] = self.func(instance)
                                         ^^^^^^^^^^^^^^^^^^^
  File "/home/lighvzkx/virtualenv/max_app/3.11/lib/python3.11/site-packages/django/urls/resolvers.py", line 715, in url_patterns
    patterns = getattr(self.urlconf_module, "urlpatterns", self.urlconf_module)
                       ^^^^^^^^^^^^^^^^^^^
  File "/home/lighvzkx/virtualenv/max_app/3.11/lib/python3.11/site-packages/django/utils/functional.py", line 57, in __get__
    res = instance.__dict__[self.name] = self.func(instance)
                                         ^^^^^^^^^^^^^^^^^^^
  File "/home/lighvzkx/virtualenv/max_app/3.11/lib/python3.11/site-packages/django/urls/resolvers.py", line 708, in urlconf_module
    return import_module(self.urlconf_name)
           ^^^^^^^^^^^^^^^^^^^^^^^^^^^^^^^^
  File "/opt/alt/python311/lib64/python3.11/importlib/__init__.py", line 126, in import_module
    return _bootstrap._gcd_import(name[level:], package, level)
           ^^^^^^^^^^^^^^^^^^^^^^^^^^^^^^^^^^^^^^^^^^^^^^^^^^^^
  File "<frozen importlib._bootstrap>", line 1204, in _gcd_import
  File "<frozen importlib._bootstrap>", line 1176, in _find_and_load
  File "<frozen importlib._bootstrap>", line 1147, in _find_and_load_unlocked
  File "<frozen importlib._bootstrap>", line 690, in _load_unlocked
  File "<frozen importlib._bootstrap_external>", line 940, in exec_module
  File "<frozen importlib._bootstrap>", line 241, in _call_with_frames_removed
  File "/home/lighvzkx/max_app/max_app_prooj/urls.py", line 22, in <module>
    path('', include('business.urls')),
             ^^^^^^^^^^^^^^^^^^^^^^^^
  File "/home/lighvzkx/virtualenv/max_app/3.11/lib/python3.11/site-packages/django/urls/conf.py", line 38, in include
    urlconf_module = import_module(urlconf_module)
                     ^^^^^^^^^^^^^^^^^^^^^^^^^^^^^
  File "/opt/alt/python311/lib64/python3.11/importlib/__init__.py", line 126, in import_module
    return _bootstrap._gcd_import(name[level:], package, level)
           ^^^^^^^^^^^^^^^^^^^^^^^^^^^^^^^^^^^^^^^^^^^^^^^^^^^^
  File "<frozen importlib._bootstrap>", line 1204, in _gcd_import
  File "<frozen importlib._bootstrap>", line 1176, in _find_and_load
  File "<frozen importlib._bootstrap>", line 1140, in _find_and_load_unlocked
ModuleNotFoundError: No module named 'business.urls'

During handling of the above exception, another exception occurred:

Traceback (most recent call last):
  File "/home/lighvzkx/virtualenv/max_app/3.11/lib/python3.11/site-packages/django/core/handlers/exception.py", line 55, in inner
    response = get_response(request)
               ^^^^^^^^^^^^^^^^^^^^^
  File "/home/lighvzkx/virtualenv/max_app/3.11/lib/python3.11/site-packages/django/utils/deprecation.py", line 134, in __call__
    response = response or self.get_response(request)
                           ^^^^^^^^^^^^^^^^^^^^^^^^^^
  File "/home/lighvzkx/virtualenv/max_app/3.11/lib/python3.11/site-packages/django/core/handlers/exception.py", line 57, in inner
    response = response_for_exception(request, exc)
               ^^^^^^^^^^^^^^^^^^^^^^^^^^^^^^^^^^^^
  File "/home/lighvzkx/virtualenv/max_app/3.11/lib/python3.11/site-packages/django/core/handlers/exception.py", line 140, in response_for_exception
    response = handle_uncaught_exception(
               ^^^^^^^^^^^^^^^^^^^^^^^^^^
  File "/home/lighvzkx/virtualenv/max_app/3.11/lib/python3.11/site-packages/django/core/handlers/exception.py", line 181, in handle_uncaught_exception
    return debug.technical_500_response(request, *exc_info)
           ^^^^^^^^^^^^^^^^^^^^^^^^^^^^^^^^^^^^^^^^^^^^^^^^
  File "/home/lighvzkx/virtualenv/max_app/3.11/lib/python3.11/site-packages/django/views/debug.py", line 67, in technical_500_response
    html = reporter.get_traceback_html()
           ^^^^^^^^^^^^^^^^^^^^^^^^^^^^^
  File "/home/lighvzkx/virtualenv/max_app/3.11/lib/python3.11/site-packages/django/views/debug.py", line 410, in get_traceback_html
    c = Context(self.get_traceback_data(), use_l10n=False)
                ^^^^^^^^^^^^^^^^^^^^^^^^^
  File "/home/lighvzkx/virtualenv/max_app/3.11/lib/python3.11/site-packages/django/views/debug.py", line 393, in get_traceback_data
    c["raising_view_name"] = get_caller(self.request)
                             ^^^^^^^^^^^^^^^^^^^^^^^^
  File "/home/lighvzkx/virtualenv/max_app/3.11/lib/python3.11/site-packages/django/views/debug.py", line 100, in get_caller
    resolver_match = resolve(request.path)
                     ^^^^^^^^^^^^^^^^^^^^^
  File "/home/lighvzkx/virtualenv/max_app/3.11/lib/python3.11/site-packages/django/urls/base.py", line 24, in resolve
    return get_resolver(urlconf).resolve(path)
           ^^^^^^^^^^^^^^^^^^^^^^^^^^^^^^^^^^^
  File "/home/lighvzkx/virtualenv/max_app/3.11/lib/python3.11/site-packages/django/urls/resolvers.py", line 663, in resolve
    for pattern in self.url_patterns:
                   ^^^^^^^^^^^^^^^^^
  File "/home/lighvzkx/virtualenv/max_app/3.11/lib/python3.11/site-packages/django/utils/functional.py", line 57, in __get__
    res = instance.__dict__[self.name] = self.func(instance)
                                         ^^^^^^^^^^^^^^^^^^^
  File "/home/lighvzkx/virtualenv/max_app/3.11/lib/python3.11/site-packages/django/urls/resolvers.py", line 715, in url_patterns
    patterns = getattr(self.urlconf_module, "urlpatterns", self.urlconf_module)
                       ^^^^^^^^^^^^^^^^^^^
  File "/home/lighvzkx/virtualenv/max_app/3.11/lib/python3.11/site-packages/django/utils/functional.py", line 57, in __get__
    res = instance.__dict__[self.name] = self.func(instance)
                                         ^^^^^^^^^^^^^^^^^^^
  File "/home/lighvzkx/virtualenv/max_app/3.11/lib/python3.11/site-packages/django/urls/resolvers.py", line 708, in urlconf_module
    return import_module(self.urlconf_name)
           ^^^^^^^^^^^^^^^^^^^^^^^^^^^^^^^^
  File "/opt/alt/python311/lib64/python3.11/importlib/__init__.py", line 126, in import_module
    return _bootstrap._gcd_import(name[level:], package, level)
           ^^^^^^^^^^^^^^^^^^^^^^^^^^^^^^^^^^^^^^^^^^^^^^^^^^^^
  File "<frozen importlib._bootstrap>", line 1204, in _gcd_import
  File "<frozen importlib._bootstrap>", line 1176, in _find_and_load
  File "<frozen importlib._bootstrap>", line 1147, in _find_and_load_unlocked
  File "<frozen importlib._bootstrap>", line 690, in _load_unlocked
  File "<frozen importlib._bootstrap_external>", line 940, in exec_module
  File "<frozen importlib._bootstrap>", line 241, in _call_with_frames_removed
  File "/home/lighvzkx/max_app/max_app_prooj/urls.py", line 22, in <module>
    path('', include('business.urls')),
             ^^^^^^^^^^^^^^^^^^^^^^^^
  File "/home/lighvzkx/virtualenv/max_app/3.11/lib/python3.11/site-packages/django/urls/conf.py", line 38, in include
    urlconf_module = import_module(urlconf_module)
                     ^^^^^^^^^^^^^^^^^^^^^^^^^^^^^
  File "/opt/alt/python311/lib64/python3.11/importlib/__init__.py", line 126, in import_module
    return _bootstrap._gcd_import(name[level:], package, level)
           ^^^^^^^^^^^^^^^^^^^^^^^^^^^^^^^^^^^^^^^^^^^^^^^^^^^^
  File "<frozen importlib._bootstrap>", line 1204, in _gcd_import
  File "<frozen importlib._bootstrap>", line 1176, in _find_and_load
  File "<frozen importlib._bootstrap>", line 1140, in _find_and_load_unlocked
ModuleNotFoundError: No module named 'business.urls'

During handling of the above exception, another exception occurred:

Traceback (most recent call last):
  File "/home/lighvzkx/virtualenv/max_app/3.11/lib/python3.11/site-packages/django/core/handlers/exception.py", line 55, in inner
    response = get_response(request)
               ^^^^^^^^^^^^^^^^^^^^^
  File "/home/lighvzkx/virtualenv/max_app/3.11/lib/python3.11/site-packages/django/utils/deprecation.py", line 134, in __call__
    response = response or self.get_response(request)
                           ^^^^^^^^^^^^^^^^^^^^^^^^^^
  File "/home/lighvzkx/virtualenv/max_app/3.11/lib/python3.11/site-packages/django/core/handlers/exception.py", line 57, in inner
    response = response_for_exception(request, exc)
               ^^^^^^^^^^^^^^^^^^^^^^^^^^^^^^^^^^^^
  File "/home/lighvzkx/virtualenv/max_app/3.11/lib/python3.11/site-packages/django/core/handlers/exception.py", line 140, in response_for_exception
    response = handle_uncaught_exception(
               ^^^^^^^^^^^^^^^^^^^^^^^^^^
  File "/home/lighvzkx/virtualenv/max_app/3.11/lib/python3.11/site-packages/django/core/handlers/exception.py", line 181, in handle_uncaught_exception
    return debug.technical_500_response(request, *exc_info)
           ^^^^^^^^^^^^^^^^^^^^^^^^^^^^^^^^^^^^^^^^^^^^^^^^
  File "/home/lighvzkx/virtualenv/max_app/3.11/lib/python3.11/site-packages/django/views/debug.py", line 67, in technical_500_response
    html = reporter.get_traceback_html()
           ^^^^^^^^^^^^^^^^^^^^^^^^^^^^^
  File "/home/lighvzkx/virtualenv/max_app/3.11/lib/python3.11/site-packages/django/views/debug.py", line 410, in get_traceback_html
    c = Context(self.get_traceback_data(), use_l10n=False)
                ^^^^^^^^^^^^^^^^^^^^^^^^^
  File "/home/lighvzkx/virtualenv/max_app/3.11/lib/python3.11/site-packages/django/views/debug.py", line 393, in get_traceback_data
    c["raising_view_name"] = get_caller(self.request)
                             ^^^^^^^^^^^^^^^^^^^^^^^^
  File "/home/lighvzkx/virtualenv/max_app/3.11/lib/python3.11/site-packages/django/views/debug.py", line 100, in get_caller
    resolver_match = resolve(request.path)
                     ^^^^^^^^^^^^^^^^^^^^^
  File "/home/lighvzkx/virtualenv/max_app/3.11/lib/python3.11/site-packages/django/urls/base.py", line 24, in resolve
    return get_resolver(urlconf).resolve(path)
           ^^^^^^^^^^^^^^^^^^^^^^^^^^^^^^^^^^^
  File "/home/lighvzkx/virtualenv/max_app/3.11/lib/python3.11/site-packages/django/urls/resolvers.py", line 663, in resolve
    for pattern in self.url_patterns:
                   ^^^^^^^^^^^^^^^^^
  File "/home/lighvzkx/virtualenv/max_app/3.11/lib/python3.11/site-packages/django/utils/functional.py", line 57, in __get__
    res = instance.__dict__[self.name] = self.func(instance)
                                         ^^^^^^^^^^^^^^^^^^^
  File "/home/lighvzkx/virtualenv/max_app/3.11/lib/python3.11/site-packages/django/urls/resolvers.py", line 715, in url_patterns
    patterns = getattr(self.urlconf_module, "urlpatterns", self.urlconf_module)
                       ^^^^^^^^^^^^^^^^^^^
  File "/home/lighvzkx/virtualenv/max_app/3.11/lib/python3.11/site-packages/django/utils/functional.py", line 57, in __get__
    res = instance.__dict__[self.name] = self.func(instance)
                                         ^^^^^^^^^^^^^^^^^^^
  File "/home/lighvzkx/virtualenv/max_app/3.11/lib/python3.11/site-packages/django/urls/resolvers.py", line 708, in urlconf_module
    return import_module(self.urlconf_name)
           ^^^^^^^^^^^^^^^^^^^^^^^^^^^^^^^^
  File "/opt/alt/python311/lib64/python3.11/importlib/__init__.py", line 126, in import_module
    return _bootstrap._gcd_import(name[level:], package, level)
           ^^^^^^^^^^^^^^^^^^^^^^^^^^^^^^^^^^^^^^^^^^^^^^^^^^^^
  File "<frozen importlib._bootstrap>", line 1204, in _gcd_import
  File "<frozen importlib._bootstrap>", line 1176, in _find_and_load
  File "<frozen importlib._bootstrap>", line 1147, in _find_and_load_unlocked
  File "<frozen importlib._bootstrap>", line 690, in _load_unlocked
  File "<frozen importlib._bootstrap_external>", line 940, in exec_module
  File "<frozen importlib._bootstrap>", line 241, in _call_with_frames_removed
  File "/home/lighvzkx/max_app/max_app_prooj/urls.py", line 22, in <module>
    path('', include('business.urls')),
             ^^^^^^^^^^^^^^^^^^^^^^^^
  File "/home/lighvzkx/virtualenv/max_app/3.11/lib/python3.11/site-packages/django/urls/conf.py", line 38, in include
    urlconf_module = import_module(urlconf_module)
                     ^^^^^^^^^^^^^^^^^^^^^^^^^^^^^
  File "/opt/alt/python311/lib64/python3.11/importlib/__init__.py", line 126, in import_module
    return _bootstrap._gcd_import(name[level:], package, level)
           ^^^^^^^^^^^^^^^^^^^^^^^^^^^^^^^^^^^^^^^^^^^^^^^^^^^^
  File "<frozen importlib._bootstrap>", line 1204, in _gcd_import
  File "<frozen importlib._bootstrap>", line 1176, in _find_and_load
  File "<frozen importlib._bootstrap>", line 1140, in _find_and_load_unlocked
ModuleNotFoundError: No module named 'business.urls'

During handling of the above exception, another exception occurred:

Traceback (most recent call last):
  File "/home/lighvzkx/virtualenv/max_app/3.11/lib/python3.11/site-packages/django/core/handlers/exception.py", line 55, in inner
    response = get_response(request)
               ^^^^^^^^^^^^^^^^^^^^^
  File "/home/lighvzkx/virtualenv/max_app/3.11/lib/python3.11/site-packages/django/utils/deprecation.py", line 134, in __call__
    response = response or self.get_response(request)
                           ^^^^^^^^^^^^^^^^^^^^^^^^^^
  File "/home/lighvzkx/virtualenv/max_app/3.11/lib/python3.11/site-packages/django/core/handlers/exception.py", line 57, in inner
    response = response_for_exception(request, exc)
               ^^^^^^^^^^^^^^^^^^^^^^^^^^^^^^^^^^^^
  File "/home/lighvzkx/virtualenv/max_app/3.11/lib/python3.11/site-packages/django/core/handlers/exception.py", line 140, in response_for_exception
    response = handle_uncaught_exception(
               ^^^^^^^^^^^^^^^^^^^^^^^^^^
  File "/home/lighvzkx/virtualenv/max_app/3.11/lib/python3.11/site-packages/django/core/handlers/exception.py", line 181, in handle_uncaught_exception
    return debug.technical_500_response(request, *exc_info)
           ^^^^^^^^^^^^^^^^^^^^^^^^^^^^^^^^^^^^^^^^^^^^^^^^
  File "/home/lighvzkx/virtualenv/max_app/3.11/lib/python3.11/site-packages/django/views/debug.py", line 67, in technical_500_response
    html = reporter.get_traceback_html()
           ^^^^^^^^^^^^^^^^^^^^^^^^^^^^^
  File "/home/lighvzkx/virtualenv/max_app/3.11/lib/python3.11/site-packages/django/views/debug.py", line 410, in get_traceback_html
    c = Context(self.get_traceback_data(), use_l10n=False)
                ^^^^^^^^^^^^^^^^^^^^^^^^^
  File "/home/lighvzkx/virtualenv/max_app/3.11/lib/python3.11/site-packages/django/views/debug.py", line 393, in get_traceback_data
    c["raising_view_name"] = get_caller(self.request)
                             ^^^^^^^^^^^^^^^^^^^^^^^^
  File "/home/lighvzkx/virtualenv/max_app/3.11/lib/python3.11/site-packages/django/views/debug.py", line 100, in get_caller
    resolver_match = resolve(request.path)
                     ^^^^^^^^^^^^^^^^^^^^^
  File "/home/lighvzkx/virtualenv/max_app/3.11/lib/python3.11/site-packages/django/urls/base.py", line 24, in resolve
    return get_resolver(urlconf).resolve(path)
           ^^^^^^^^^^^^^^^^^^^^^^^^^^^^^^^^^^^
  File "/home/lighvzkx/virtualenv/max_app/3.11/lib/python3.11/site-packages/django/urls/resolvers.py", line 663, in resolve
    for pattern in self.url_patterns:
                   ^^^^^^^^^^^^^^^^^
  File "/home/lighvzkx/virtualenv/max_app/3.11/lib/python3.11/site-packages/django/utils/functional.py", line 57, in __get__
    res = instance.__dict__[self.name] = self.func(instance)
                                         ^^^^^^^^^^^^^^^^^^^
  File "/home/lighvzkx/virtualenv/max_app/3.11/lib/python3.11/site-packages/django/urls/resolvers.py", line 715, in url_patterns
    patterns = getattr(self.urlconf_module, "urlpatterns", self.urlconf_module)
                       ^^^^^^^^^^^^^^^^^^^
  File "/home/lighvzkx/virtualenv/max_app/3.11/lib/python3.11/site-packages/django/utils/functional.py", line 57, in __get__
    res = instance.__dict__[self.name] = self.func(instance)
                                         ^^^^^^^^^^^^^^^^^^^
  File "/home/lighvzkx/virtualenv/max_app/3.11/lib/python3.11/site-packages/django/urls/resolvers.py", line 708, in urlconf_module
    return import_module(self.urlconf_name)
           ^^^^^^^^^^^^^^^^^^^^^^^^^^^^^^^^
  File "/opt/alt/python311/lib64/python3.11/importlib/__init__.py", line 126, in import_module
    return _bootstrap._gcd_import(name[level:], package, level)
           ^^^^^^^^^^^^^^^^^^^^^^^^^^^^^^^^^^^^^^^^^^^^^^^^^^^^
  File "<frozen importlib._bootstrap>", line 1204, in _gcd_import
  File "<frozen importlib._bootstrap>", line 1176, in _find_and_load
  File "<frozen importlib._bootstrap>", line 1147, in _find_and_load_unlocked
  File "<frozen importlib._bootstrap>", line 690, in _load_unlocked
  File "<frozen importlib._bootstrap_external>", line 940, in exec_module
  File "<frozen importlib._bootstrap>", line 241, in _call_with_frames_removed
  File "/home/lighvzkx/max_app/max_app_prooj/urls.py", line 22, in <module>
    path('', include('business.urls')),
             ^^^^^^^^^^^^^^^^^^^^^^^^
  File "/home/lighvzkx/virtualenv/max_app/3.11/lib/python3.11/site-packages/django/urls/conf.py", line 38, in include
    urlconf_module = import_module(urlconf_module)
                     ^^^^^^^^^^^^^^^^^^^^^^^^^^^^^
  File "/opt/alt/python311/lib64/python3.11/importlib/__init__.py", line 126, in import_module
    return _bootstrap._gcd_import(name[level:], package, level)
           ^^^^^^^^^^^^^^^^^^^^^^^^^^^^^^^^^^^^^^^^^^^^^^^^^^^^
  File "<frozen importlib._bootstrap>", line 1204, in _gcd_import
  File "<frozen importlib._bootstrap>", line 1176, in _find_and_load
  File "<frozen importlib._bootstrap>", line 1140, in _find_and_load_unlocked
ModuleNotFoundError: No module named 'business.urls'

During handling of the above exception, another exception occurred:

Traceback (most recent call last):
  File "/home/lighvzkx/virtualenv/max_app/3.11/lib/python3.11/site-packages/django/core/handlers/exception.py", line 55, in inner
    response = get_response(request)
               ^^^^^^^^^^^^^^^^^^^^^
  File "/home/lighvzkx/virtualenv/max_app/3.11/lib/python3.11/site-packages/django/utils/deprecation.py", line 134, in __call__
    response = response or self.get_response(request)
                           ^^^^^^^^^^^^^^^^^^^^^^^^^^
  File "/home/lighvzkx/virtualenv/max_app/3.11/lib/python3.11/site-packages/django/core/handlers/exception.py", line 57, in inner
    response = response_for_exception(request, exc)
               ^^^^^^^^^^^^^^^^^^^^^^^^^^^^^^^^^^^^
  File "/home/lighvzkx/virtualenv/max_app/3.11/lib/python3.11/site-packages/django/core/handlers/exception.py", line 140, in response_for_exception
    response = handle_uncaught_exception(
               ^^^^^^^^^^^^^^^^^^^^^^^^^^
  File "/home/lighvzkx/virtualenv/max_app/3.11/lib/python3.11/site-packages/django/core/handlers/exception.py", line 181, in handle_uncaught_exception
    return debug.technical_500_response(request, *exc_info)
           ^^^^^^^^^^^^^^^^^^^^^^^^^^^^^^^^^^^^^^^^^^^^^^^^
  File "/home/lighvzkx/virtualenv/max_app/3.11/lib/python3.11/site-packages/django/views/debug.py", line 67, in technical_500_response
    html = reporter.get_traceback_html()
           ^^^^^^^^^^^^^^^^^^^^^^^^^^^^^
  File "/home/lighvzkx/virtualenv/max_app/3.11/lib/python3.11/site-packages/django/views/debug.py", line 410, in get_traceback_html
    c = Context(self.get_traceback_data(), use_l10n=False)
                ^^^^^^^^^^^^^^^^^^^^^^^^^
  File "/home/lighvzkx/virtualenv/max_app/3.11/lib/python3.11/site-packages/django/views/debug.py", line 393, in get_traceback_data
    c["raising_view_name"] = get_caller(self.request)
                             ^^^^^^^^^^^^^^^^^^^^^^^^
  File "/home/lighvzkx/virtualenv/max_app/3.11/lib/python3.11/site-packages/django/views/debug.py", line 100, in get_caller
    resolver_match = resolve(request.path)
                     ^^^^^^^^^^^^^^^^^^^^^
  File "/home/lighvzkx/virtualenv/max_app/3.11/lib/python3.11/site-packages/django/urls/base.py", line 24, in resolve
    return get_resolver(urlconf).resolve(path)
           ^^^^^^^^^^^^^^^^^^^^^^^^^^^^^^^^^^^
  File "/home/lighvzkx/virtualenv/max_app/3.11/lib/python3.11/site-packages/django/urls/resolvers.py", line 663, in resolve
    for pattern in self.url_patterns:
                   ^^^^^^^^^^^^^^^^^
  File "/home/lighvzkx/virtualenv/max_app/3.11/lib/python3.11/site-packages/django/utils/functional.py", line 57, in __get__
    res = instance.__dict__[self.name] = self.func(instance)
                                         ^^^^^^^^^^^^^^^^^^^
  File "/home/lighvzkx/virtualenv/max_app/3.11/lib/python3.11/site-packages/django/urls/resolvers.py", line 715, in url_patterns
    patterns = getattr(self.urlconf_module, "urlpatterns", self.urlconf_module)
                       ^^^^^^^^^^^^^^^^^^^
  File "/home/lighvzkx/virtualenv/max_app/3.11/lib/python3.11/site-packages/django/utils/functional.py", line 57, in __get__
    res = instance.__dict__[self.name] = self.func(instance)
                                         ^^^^^^^^^^^^^^^^^^^
  File "/home/lighvzkx/virtualenv/max_app/3.11/lib/python3.11/site-packages/django/urls/resolvers.py", line 708, in urlconf_module
    return import_module(self.urlconf_name)
           ^^^^^^^^^^^^^^^^^^^^^^^^^^^^^^^^
  File "/opt/alt/python311/lib64/python3.11/importlib/__init__.py", line 126, in import_module
    return _bootstrap._gcd_import(name[level:], package, level)
           ^^^^^^^^^^^^^^^^^^^^^^^^^^^^^^^^^^^^^^^^^^^^^^^^^^^^
  File "<frozen importlib._bootstrap>", line 1204, in _gcd_import
  File "<frozen importlib._bootstrap>", line 1176, in _find_and_load
  File "<frozen importlib._bootstrap>", line 1147, in _find_and_load_unlocked
  File "<frozen importlib._bootstrap>", line 690, in _load_unlocked
  File "<frozen importlib._bootstrap_external>", line 940, in exec_module
  File "<frozen importlib._bootstrap>", line 241, in _call_with_frames_removed
  File "/home/lighvzkx/max_app/max_app_prooj/urls.py", line 22, in <module>
    path('', include('business.urls')),
             ^^^^^^^^^^^^^^^^^^^^^^^^
  File "/home/lighvzkx/virtualenv/max_app/3.11/lib/python3.11/site-packages/django/urls/conf.py", line 38, in include
    urlconf_module = import_module(urlconf_module)
                     ^^^^^^^^^^^^^^^^^^^^^^^^^^^^^
  File "/opt/alt/python311/lib64/python3.11/importlib/__init__.py", line 126, in import_module
    return _bootstrap._gcd_import(name[level:], package, level)
           ^^^^^^^^^^^^^^^^^^^^^^^^^^^^^^^^^^^^^^^^^^^^^^^^^^^^
  File "<frozen importlib._bootstrap>", line 1204, in _gcd_import
  File "<frozen importlib._bootstrap>", line 1176, in _find_and_load
  File "<frozen importlib._bootstrap>", line 1140, in _find_and_load_unlocked
ModuleNotFoundError: No module named 'business.urls'

During handling of the above exception, another exception occurred:

Traceback (most recent call last):
  File "/home/lighvzkx/virtualenv/max_app/3.11/lib/python3.11/site-packages/django/core/handlers/exception.py", line 55, in inner
    response = get_response(request)
               ^^^^^^^^^^^^^^^^^^^^^
  File "/home/lighvzkx/virtualenv/max_app/3.11/lib/python3.11/site-packages/django/utils/deprecation.py", line 134, in __call__
    response = response or self.get_response(request)
                           ^^^^^^^^^^^^^^^^^^^^^^^^^^
  File "/home/lighvzkx/virtualenv/max_app/3.11/lib/python3.11/site-packages/django/core/handlers/exception.py", line 57, in inner
    response = response_for_exception(request, exc)
               ^^^^^^^^^^^^^^^^^^^^^^^^^^^^^^^^^^^^
  File "/home/lighvzkx/virtualenv/max_app/3.11/lib/python3.11/site-packages/django/core/handlers/exception.py", line 140, in response_for_exception
    response = handle_uncaught_exception(
               ^^^^^^^^^^^^^^^^^^^^^^^^^^
  File "/home/lighvzkx/virtualenv/max_app/3.11/lib/python3.11/site-packages/django/core/handlers/exception.py", line 181, in handle_uncaught_exception
    return debug.technical_500_response(request, *exc_info)
           ^^^^^^^^^^^^^^^^^^^^^^^^^^^^^^^^^^^^^^^^^^^^^^^^
  File "/home/lighvzkx/virtualenv/max_app/3.11/lib/python3.11/site-packages/django/views/debug.py", line 67, in technical_500_response
    html = reporter.get_traceback_html()
           ^^^^^^^^^^^^^^^^^^^^^^^^^^^^^
  File "/home/lighvzkx/virtualenv/max_app/3.11/lib/python3.11/site-packages/django/views/debug.py", line 410, in get_traceback_html
    c = Context(self.get_traceback_data(), use_l10n=False)
                ^^^^^^^^^^^^^^^^^^^^^^^^^
  File "/home/lighvzkx/virtualenv/max_app/3.11/lib/python3.11/site-packages/django/views/debug.py", line 393, in get_traceback_data
    c["raising_view_name"] = get_caller(self.request)
                             ^^^^^^^^^^^^^^^^^^^^^^^^
  File "/home/lighvzkx/virtualenv/max_app/3.11/lib/python3.11/site-packages/django/views/debug.py", line 100, in get_caller
    resolver_match = resolve(request.path)
                     ^^^^^^^^^^^^^^^^^^^^^
  File "/home/lighvzkx/virtualenv/max_app/3.11/lib/python3.11/site-packages/django/urls/base.py", line 24, in resolve
    return get_resolver(urlconf).resolve(path)
           ^^^^^^^^^^^^^^^^^^^^^^^^^^^^^^^^^^^
  File "/home/lighvzkx/virtualenv/max_app/3.11/lib/python3.11/site-packages/django/urls/resolvers.py", line 663, in resolve
    for pattern in self.url_patterns:
                   ^^^^^^^^^^^^^^^^^
  File "/home/lighvzkx/virtualenv/max_app/3.11/lib/python3.11/site-packages/django/utils/functional.py", line 57, in __get__
    res = instance.__dict__[self.name] = self.func(instance)
                                         ^^^^^^^^^^^^^^^^^^^
  File "/home/lighvzkx/virtualenv/max_app/3.11/lib/python3.11/site-packages/django/urls/resolvers.py", line 715, in url_patterns
    patterns = getattr(self.urlconf_module, "urlpatterns", self.urlconf_module)
                       ^^^^^^^^^^^^^^^^^^^
  File "/home/lighvzkx/virtualenv/max_app/3.11/lib/python3.11/site-packages/django/utils/functional.py", line 57, in __get__
    res = instance.__dict__[self.name] = self.func(instance)
                                         ^^^^^^^^^^^^^^^^^^^
  File "/home/lighvzkx/virtualenv/max_app/3.11/lib/python3.11/site-packages/django/urls/resolvers.py", line 708, in urlconf_module
    return import_module(self.urlconf_name)
           ^^^^^^^^^^^^^^^^^^^^^^^^^^^^^^^^
  File "/opt/alt/python311/lib64/python3.11/importlib/__init__.py", line 126, in import_module
    return _bootstrap._gcd_import(name[level:], package, level)
           ^^^^^^^^^^^^^^^^^^^^^^^^^^^^^^^^^^^^^^^^^^^^^^^^^^^^
  File "<frozen importlib._bootstrap>", line 1204, in _gcd_import
  File "<frozen importlib._bootstrap>", line 1176, in _find_and_load
  File "<frozen importlib._bootstrap>", line 1147, in _find_and_load_unlocked
  File "<frozen importlib._bootstrap>", line 690, in _load_unlocked
  File "<frozen importlib._bootstrap_external>", line 940, in exec_module
  File "<frozen importlib._bootstrap>", line 241, in _call_with_frames_removed
  File "/home/lighvzkx/max_app/max_app_prooj/urls.py", line 22, in <module>
    path('', include('business.urls')),
             ^^^^^^^^^^^^^^^^^^^^^^^^
  File "/home/lighvzkx/virtualenv/max_app/3.11/lib/python3.11/site-packages/django/urls/conf.py", line 38, in include
    urlconf_module = import_module(urlconf_module)
                     ^^^^^^^^^^^^^^^^^^^^^^^^^^^^^
  File "/opt/alt/python311/lib64/python3.11/importlib/__init__.py", line 126, in import_module
    return _bootstrap._gcd_import(name[level:], package, level)
           ^^^^^^^^^^^^^^^^^^^^^^^^^^^^^^^^^^^^^^^^^^^^^^^^^^^^
  File "<frozen importlib._bootstrap>", line 1204, in _gcd_import
  File "<frozen importlib._bootstrap>", line 1176, in _find_and_load
  File "<frozen importlib._bootstrap>", line 1140, in _find_and_load_unlocked
ModuleNotFoundError: No module named 'business.urls'

During handling of the above exception, another exception occurred:

Traceback (most recent call last):
  File "/home/lighvzkx/virtualenv/max_app/3.11/lib/python3.11/site-packages/django/core/handlers/exception.py", line 55, in inner
    response = get_response(request)
               ^^^^^^^^^^^^^^^^^^^^^
  File "/home/lighvzkx/virtualenv/max_app/3.11/lib/python3.11/site-packages/django/utils/deprecation.py", line 134, in __call__
    response = response or self.get_response(request)
                           ^^^^^^^^^^^^^^^^^^^^^^^^^^
  File "/home/lighvzkx/virtualenv/max_app/3.11/lib/python3.11/site-packages/django/core/handlers/exception.py", line 57, in inner
    response = response_for_exception(request, exc)
               ^^^^^^^^^^^^^^^^^^^^^^^^^^^^^^^^^^^^
  File "/home/lighvzkx/virtualenv/max_app/3.11/lib/python3.11/site-packages/django/core/handlers/exception.py", line 140, in response_for_exception
    response = handle_uncaught_exception(
               ^^^^^^^^^^^^^^^^^^^^^^^^^^
  File "/home/lighvzkx/virtualenv/max_app/3.11/lib/python3.11/site-packages/django/core/handlers/exception.py", line 181, in handle_uncaught_exception
    return debug.technical_500_response(request, *exc_info)
           ^^^^^^^^^^^^^^^^^^^^^^^^^^^^^^^^^^^^^^^^^^^^^^^^
  File "/home/lighvzkx/virtualenv/max_app/3.11/lib/python3.11/site-packages/django/views/debug.py", line 67, in technical_500_response
    html = reporter.get_traceback_html()
           ^^^^^^^^^^^^^^^^^^^^^^^^^^^^^
  File "/home/lighvzkx/virtualenv/max_app/3.11/lib/python3.11/site-packages/django/views/debug.py", line 410, in get_traceback_html
    c = Context(self.get_traceback_data(), use_l10n=False)
                ^^^^^^^^^^^^^^^^^^^^^^^^^
  File "/home/lighvzkx/virtualenv/max_app/3.11/lib/python3.11/site-packages/django/views/debug.py", line 393, in get_traceback_data
    c["raising_view_name"] = get_caller(self.request)
                             ^^^^^^^^^^^^^^^^^^^^^^^^
  File "/home/lighvzkx/virtualenv/max_app/3.11/lib/python3.11/site-packages/django/views/debug.py", line 100, in get_caller
    resolver_match = resolve(request.path)
                     ^^^^^^^^^^^^^^^^^^^^^
  File "/home/lighvzkx/virtualenv/max_app/3.11/lib/python3.11/site-packages/django/urls/base.py", line 24, in resolve
    return get_resolver(urlconf).resolve(path)
           ^^^^^^^^^^^^^^^^^^^^^^^^^^^^^^^^^^^
  File "/home/lighvzkx/virtualenv/max_app/3.11/lib/python3.11/site-packages/django/urls/resolvers.py", line 663, in resolve
    for pattern in self.url_patterns:
                   ^^^^^^^^^^^^^^^^^
  File "/home/lighvzkx/virtualenv/max_app/3.11/lib/python3.11/site-packages/django/utils/functional.py", line 57, in __get__
    res = instance.__dict__[self.name] = self.func(instance)
                                         ^^^^^^^^^^^^^^^^^^^
  File "/home/lighvzkx/virtualenv/max_app/3.11/lib/python3.11/site-packages/django/urls/resolvers.py", line 715, in url_patterns
    patterns = getattr(self.urlconf_module, "urlpatterns", self.urlconf_module)
                       ^^^^^^^^^^^^^^^^^^^
  File "/home/lighvzkx/virtualenv/max_app/3.11/lib/python3.11/site-packages/django/utils/functional.py", line 57, in __get__
    res = instance.__dict__[self.name] = self.func(instance)
                                         ^^^^^^^^^^^^^^^^^^^
  File "/home/lighvzkx/virtualenv/max_app/3.11/lib/python3.11/site-packages/django/urls/resolvers.py", line 708, in urlconf_module
    return import_module(self.urlconf_name)
           ^^^^^^^^^^^^^^^^^^^^^^^^^^^^^^^^
  File "/opt/alt/python311/lib64/python3.11/importlib/__init__.py", line 126, in import_module
    return _bootstrap._gcd_import(name[level:], package, level)
           ^^^^^^^^^^^^^^^^^^^^^^^^^^^^^^^^^^^^^^^^^^^^^^^^^^^^
  File "<frozen importlib._bootstrap>", line 1204, in _gcd_import
  File "<frozen importlib._bootstrap>", line 1176, in _find_and_load
  File "<frozen importlib._bootstrap>", line 1147, in _find_and_load_unlocked
  File "<frozen importlib._bootstrap>", line 690, in _load_unlocked
  File "<frozen importlib._bootstrap_external>", line 940, in exec_module
  File "<frozen importlib._bootstrap>", line 241, in _call_with_frames_removed
  File "/home/lighvzkx/max_app/max_app_prooj/urls.py", line 22, in <module>
    path('', include('business.urls')),
             ^^^^^^^^^^^^^^^^^^^^^^^^
  File "/home/lighvzkx/virtualenv/max_app/3.11/lib/python3.11/site-packages/django/urls/conf.py", line 38, in include
    urlconf_module = import_module(urlconf_module)
                     ^^^^^^^^^^^^^^^^^^^^^^^^^^^^^
  File "/opt/alt/python311/lib64/python3.11/importlib/__init__.py", line 126, in import_module
    return _bootstrap._gcd_import(name[level:], package, level)
           ^^^^^^^^^^^^^^^^^^^^^^^^^^^^^^^^^^^^^^^^^^^^^^^^^^^^
  File "<frozen importlib._bootstrap>", line 1204, in _gcd_import
  File "<frozen importlib._bootstrap>", line 1176, in _find_and_load
  File "<frozen importlib._bootstrap>", line 1140, in _find_and_load_unlocked
ModuleNotFoundError: No module named 'business.urls'

During handling of the above exception, another exception occurred:

Traceback (most recent call last):
  File "/home/lighvzkx/virtualenv/max_app/3.11/lib/python3.11/site-packages/django/core/handlers/wsgi.py", line 124, in __call__
    response = self.get_response(request)
               ^^^^^^^^^^^^^^^^^^^^^^^^^^
  File "/home/lighvzkx/virtualenv/max_app/3.11/lib/python3.11/site-packages/django/core/handlers/base.py", line 140, in get_response
    response = self._middleware_chain(request)
               ^^^^^^^^^^^^^^^^^^^^^^^^^^^^^^^
  File "/home/lighvzkx/virtualenv/max_app/3.11/lib/python3.11/site-packages/django/core/handlers/exception.py", line 57, in inner
    response = response_for_exception(request, exc)
               ^^^^^^^^^^^^^^^^^^^^^^^^^^^^^^^^^^^^
  File "/home/lighvzkx/virtualenv/max_app/3.11/lib/python3.11/site-packages/django/core/handlers/exception.py", line 140, in response_for_exception
    response = handle_uncaught_exception(
               ^^^^^^^^^^^^^^^^^^^^^^^^^^
  File "/home/lighvzkx/virtualenv/max_app/3.11/lib/python3.11/site-packages/django/core/handlers/exception.py", line 181, in handle_uncaught_exception
    return debug.technical_500_response(request, *exc_info)
           ^^^^^^^^^^^^^^^^^^^^^^^^^^^^^^^^^^^^^^^^^^^^^^^^
  File "/home/lighvzkx/virtualenv/max_app/3.11/lib/python3.11/site-packages/django/views/debug.py", line 67, in technical_500_response
    html = reporter.get_traceback_html()
           ^^^^^^^^^^^^^^^^^^^^^^^^^^^^^
  File "/home/lighvzkx/virtualenv/max_app/3.11/lib/python3.11/site-packages/django/views/debug.py", line 410, in get_traceback_html
    c = Context(self.get_traceback_data(), use_l10n=False)
                ^^^^^^^^^^^^^^^^^^^^^^^^^
  File "/home/lighvzkx/virtualenv/max_app/3.11/lib/python3.11/site-packages/django/views/debug.py", line 393, in get_traceback_data
    c["raising_view_name"] = get_caller(self.request)
                             ^^^^^^^^^^^^^^^^^^^^^^^^
  File "/home/lighvzkx/virtualenv/max_app/3.11/lib/python3.11/site-packages/django/views/debug.py", line 100, in get_caller
    resolver_match = resolve(request.path)
                     ^^^^^^^^^^^^^^^^^^^^^
  File "/home/lighvzkx/virtualenv/max_app/3.11/lib/python3.11/site-packages/django/urls/base.py", line 24, in resolve
    return get_resolver(urlconf).resolve(path)
           ^^^^^^^^^^^^^^^^^^^^^^^^^^^^^^^^^^^
  File "/home/lighvzkx/virtualenv/max_app/3.11/lib/python3.11/site-packages/django/urls/resolvers.py", line 663, in resolve
    for pattern in self.url_patterns:
                   ^^^^^^^^^^^^^^^^^
  File "/home/lighvzkx/virtualenv/max_app/3.11/lib/python3.11/site-packages/django/utils/functional.py", line 57, in __get__
    res = instance.__dict__[self.name] = self.func(instance)
                                         ^^^^^^^^^^^^^^^^^^^
  File "/home/lighvzkx/virtualenv/max_app/3.11/lib/python3.11/site-packages/django/urls/resolvers.py", line 715, in url_patterns
    patterns = getattr(self.urlconf_module, "urlpatterns", self.urlconf_module)
                       ^^^^^^^^^^^^^^^^^^^
  File "/home/lighvzkx/virtualenv/max_app/3.11/lib/python3.11/site-packages/django/utils/functional.py", line 57, in __get__
    res = instance.__dict__[self.name] = self.func(instance)
                                         ^^^^^^^^^^^^^^^^^^^
  File "/home/lighvzkx/virtualenv/max_app/3.11/lib/python3.11/site-packages/django/urls/resolvers.py", line 708, in urlconf_module
    return import_module(self.urlconf_name)
           ^^^^^^^^^^^^^^^^^^^^^^^^^^^^^^^^
  File "/opt/alt/python311/lib64/python3.11/importlib/__init__.py", line 126, in import_module
    return _bootstrap._gcd_import(name[level:], package, level)
           ^^^^^^^^^^^^^^^^^^^^^^^^^^^^^^^^^^^^^^^^^^^^^^^^^^^^
  File "<frozen importlib._bootstrap>", line 1204, in _gcd_import
  File "<frozen importlib._bootstrap>", line 1176, in _find_and_load
  File "<frozen importlib._bootstrap>", line 1147, in _find_and_load_unlocked
  File "<frozen importlib._bootstrap>", line 690, in _load_unlocked
  File "<frozen importlib._bootstrap_external>", line 940, in exec_module
  File "<frozen importlib._bootstrap>", line 241, in _call_with_frames_removed
  File "/home/lighvzkx/max_app/max_app_prooj/urls.py", line 22, in <module>
    path('', include('business.urls')),
             ^^^^^^^^^^^^^^^^^^^^^^^^
  File "/home/lighvzkx/virtualenv/max_app/3.11/lib/python3.11/site-packages/django/urls/conf.py", line 38, in include
    urlconf_module = import_module(urlconf_module)
                     ^^^^^^^^^^^^^^^^^^^^^^^^^^^^^
  File "/opt/alt/python311/lib64/python3.11/importlib/__init__.py", line 126, in import_module
    return _bootstrap._gcd_import(name[level:], package, level)
           ^^^^^^^^^^^^^^^^^^^^^^^^^^^^^^^^^^^^^^^^^^^^^^^^^^^^
  File "<frozen importlib._bootstrap>", line 1204, in _gcd_import
  File "<frozen importlib._bootstrap>", line 1176, in _find_and_load
  File "<frozen importlib._bootstrap>", line 1140, in _find_and_load_unlocked
ModuleNotFoundError: No module named 'business.urls'
[ERROR] [UID:13895][3513] wsgiAppHandler pApp->start_response() return NULL.
Traceback (most recent call last):
  File "/home/lighvzkx/virtualenv/max_app/3.11/lib/python3.11/site-packages/django/core/handlers/exception.py", line 55, in inner
    response = get_response(request)
               ^^^^^^^^^^^^^^^^^^^^^
  File "/home/lighvzkx/virtualenv/max_app/3.11/lib/python3.11/site-packages/django/core/handlers/base.py", line 181, in _get_response
    callback, callback_args, callback_kwargs = self.resolve_request(request)
                                               ^^^^^^^^^^^^^^^^^^^^^^^^^^^^^
  File "/home/lighvzkx/virtualenv/max_app/3.11/lib/python3.11/site-packages/django/core/handlers/base.py", line 313, in resolve_request
    resolver_match = resolver.resolve(request.path_info)
                     ^^^^^^^^^^^^^^^^^^^^^^^^^^^^^^^^^^^
  File "/home/lighvzkx/virtualenv/max_app/3.11/lib/python3.11/site-packages/django/urls/resolvers.py", line 663, in resolve
    for pattern in self.url_patterns:
                   ^^^^^^^^^^^^^^^^^
  File "/home/lighvzkx/virtualenv/max_app/3.11/lib/python3.11/site-packages/django/utils/functional.py", line 57, in __get__
    res = instance.__dict__[self.name] = self.func(instance)
                                         ^^^^^^^^^^^^^^^^^^^
  File "/home/lighvzkx/virtualenv/max_app/3.11/lib/python3.11/site-packages/django/urls/resolvers.py", line 715, in url_patterns
    patterns = getattr(self.urlconf_module, "urlpatterns", self.urlconf_module)
                       ^^^^^^^^^^^^^^^^^^^
  File "/home/lighvzkx/virtualenv/max_app/3.11/lib/python3.11/site-packages/django/utils/functional.py", line 57, in __get__
    res = instance.__dict__[self.name] = self.func(instance)
                                         ^^^^^^^^^^^^^^^^^^^
  File "/home/lighvzkx/virtualenv/max_app/3.11/lib/python3.11/site-packages/django/urls/resolvers.py", line 708, in urlconf_module
    return import_module(self.urlconf_name)
           ^^^^^^^^^^^^^^^^^^^^^^^^^^^^^^^^
  File "/opt/alt/python311/lib64/python3.11/importlib/__init__.py", line 126, in import_module
    return _bootstrap._gcd_import(name[level:], package, level)
           ^^^^^^^^^^^^^^^^^^^^^^^^^^^^^^^^^^^^^^^^^^^^^^^^^^^^
  File "<frozen importlib._bootstrap>", line 1204, in _gcd_import
  File "<frozen importlib._bootstrap>", line 1176, in _find_and_load
  File "<frozen importlib._bootstrap>", line 1147, in _find_and_load_unlocked
  File "<frozen importlib._bootstrap>", line 690, in _load_unlocked
  File "<frozen importlib._bootstrap_external>", line 940, in exec_module
  File "<frozen importlib._bootstrap>", line 241, in _call_with_frames_removed
  File "/home/lighvzkx/max_app/max_app_prooj/urls.py", line 22, in <module>
    path('', include('business.urls')),
             ^^^^^^^^^^^^^^^^^^^^^^^^
  File "/home/lighvzkx/virtualenv/max_app/3.11/lib/python3.11/site-packages/django/urls/conf.py", line 38, in include
    urlconf_module = import_module(urlconf_module)
                     ^^^^^^^^^^^^^^^^^^^^^^^^^^^^^
  File "/opt/alt/python311/lib64/python3.11/importlib/__init__.py", line 126, in import_module
    return _bootstrap._gcd_import(name[level:], package, level)
           ^^^^^^^^^^^^^^^^^^^^^^^^^^^^^^^^^^^^^^^^^^^^^^^^^^^^
  File "<frozen importlib._bootstrap>", line 1204, in _gcd_import
  File "<frozen importlib._bootstrap>", line 1176, in _find_and_load
  File "<frozen importlib._bootstrap>", line 1140, in _find_and_load_unlocked
ModuleNotFoundError: No module named 'business.urls'

During handling of the above exception, another exception occurred:

Traceback (most recent call last):
  File "/home/lighvzkx/virtualenv/max_app/3.11/lib/python3.11/site-packages/django/core/handlers/exception.py", line 55, in inner
    response = get_response(request)
               ^^^^^^^^^^^^^^^^^^^^^
  File "/home/lighvzkx/virtualenv/max_app/3.11/lib/python3.11/site-packages/django/utils/deprecation.py", line 134, in __call__
    response = response or self.get_response(request)
                           ^^^^^^^^^^^^^^^^^^^^^^^^^^
  File "/home/lighvzkx/virtualenv/max_app/3.11/lib/python3.11/site-packages/django/core/handlers/exception.py", line 57, in inner
    response = response_for_exception(request, exc)
               ^^^^^^^^^^^^^^^^^^^^^^^^^^^^^^^^^^^^
  File "/home/lighvzkx/virtualenv/max_app/3.11/lib/python3.11/site-packages/django/core/handlers/exception.py", line 140, in response_for_exception
    response = handle_uncaught_exception(
               ^^^^^^^^^^^^^^^^^^^^^^^^^^
  File "/home/lighvzkx/virtualenv/max_app/3.11/lib/python3.11/site-packages/django/core/handlers/exception.py", line 181, in handle_uncaught_exception
    return debug.technical_500_response(request, *exc_info)
           ^^^^^^^^^^^^^^^^^^^^^^^^^^^^^^^^^^^^^^^^^^^^^^^^
  File "/home/lighvzkx/virtualenv/max_app/3.11/lib/python3.11/site-packages/django/views/debug.py", line 67, in technical_500_response
    html = reporter.get_traceback_html()
           ^^^^^^^^^^^^^^^^^^^^^^^^^^^^^
  File "/home/lighvzkx/virtualenv/max_app/3.11/lib/python3.11/site-packages/django/views/debug.py", line 410, in get_traceback_html
    c = Context(self.get_traceback_data(), use_l10n=False)
                ^^^^^^^^^^^^^^^^^^^^^^^^^
  File "/home/lighvzkx/virtualenv/max_app/3.11/lib/python3.11/site-packages/django/views/debug.py", line 393, in get_traceback_data
    c["raising_view_name"] = get_caller(self.request)
                             ^^^^^^^^^^^^^^^^^^^^^^^^
  File "/home/lighvzkx/virtualenv/max_app/3.11/lib/python3.11/site-packages/django/views/debug.py", line 100, in get_caller
    resolver_match = resolve(request.path)
                     ^^^^^^^^^^^^^^^^^^^^^
  File "/home/lighvzkx/virtualenv/max_app/3.11/lib/python3.11/site-packages/django/urls/base.py", line 24, in resolve
    return get_resolver(urlconf).resolve(path)
           ^^^^^^^^^^^^^^^^^^^^^^^^^^^^^^^^^^^
  File "/home/lighvzkx/virtualenv/max_app/3.11/lib/python3.11/site-packages/django/urls/resolvers.py", line 663, in resolve
    for pattern in self.url_patterns:
                   ^^^^^^^^^^^^^^^^^
  File "/home/lighvzkx/virtualenv/max_app/3.11/lib/python3.11/site-packages/django/utils/functional.py", line 57, in __get__
    res = instance.__dict__[self.name] = self.func(instance)
                                         ^^^^^^^^^^^^^^^^^^^
  File "/home/lighvzkx/virtualenv/max_app/3.11/lib/python3.11/site-packages/django/urls/resolvers.py", line 715, in url_patterns
    patterns = getattr(self.urlconf_module, "urlpatterns", self.urlconf_module)
                       ^^^^^^^^^^^^^^^^^^^
  File "/home/lighvzkx/virtualenv/max_app/3.11/lib/python3.11/site-packages/django/utils/functional.py", line 57, in __get__
    res = instance.__dict__[self.name] = self.func(instance)
                                         ^^^^^^^^^^^^^^^^^^^
  File "/home/lighvzkx/virtualenv/max_app/3.11/lib/python3.11/site-packages/django/urls/resolvers.py", line 708, in urlconf_module
    return import_module(self.urlconf_name)
           ^^^^^^^^^^^^^^^^^^^^^^^^^^^^^^^^
  File "/opt/alt/python311/lib64/python3.11/importlib/__init__.py", line 126, in import_module
    return _bootstrap._gcd_import(name[level:], package, level)
           ^^^^^^^^^^^^^^^^^^^^^^^^^^^^^^^^^^^^^^^^^^^^^^^^^^^^
  File "<frozen importlib._bootstrap>", line 1204, in _gcd_import
  File "<frozen importlib._bootstrap>", line 1176, in _find_and_load
  File "<frozen importlib._bootstrap>", line 1147, in _find_and_load_unlocked
  File "<frozen importlib._bootstrap>", line 690, in _load_unlocked
  File "<frozen importlib._bootstrap_external>", line 940, in exec_module
  File "<frozen importlib._bootstrap>", line 241, in _call_with_frames_removed
  File "/home/lighvzkx/max_app/max_app_prooj/urls.py", line 22, in <module>
    path('', include('business.urls')),
             ^^^^^^^^^^^^^^^^^^^^^^^^
  File "/home/lighvzkx/virtualenv/max_app/3.11/lib/python3.11/site-packages/django/urls/conf.py", line 38, in include
    urlconf_module = import_module(urlconf_module)
                     ^^^^^^^^^^^^^^^^^^^^^^^^^^^^^
  File "/opt/alt/python311/lib64/python3.11/importlib/__init__.py", line 126, in import_module
    return _bootstrap._gcd_import(name[level:], package, level)
           ^^^^^^^^^^^^^^^^^^^^^^^^^^^^^^^^^^^^^^^^^^^^^^^^^^^^
  File "<frozen importlib._bootstrap>", line 1204, in _gcd_import
  File "<frozen importlib._bootstrap>", line 1176, in _find_and_load
  File "<frozen importlib._bootstrap>", line 1140, in _find_and_load_unlocked
ModuleNotFoundError: No module named 'business.urls'

During handling of the above exception, another exception occurred:

Traceback (most recent call last):
  File "/home/lighvzkx/virtualenv/max_app/3.11/lib/python3.11/site-packages/django/core/handlers/exception.py", line 55, in inner
    response = get_response(request)
               ^^^^^^^^^^^^^^^^^^^^^
  File "/home/lighvzkx/virtualenv/max_app/3.11/lib/python3.11/site-packages/django/utils/deprecation.py", line 134, in __call__
    response = response or self.get_response(request)
                           ^^^^^^^^^^^^^^^^^^^^^^^^^^
  File "/home/lighvzkx/virtualenv/max_app/3.11/lib/python3.11/site-packages/django/core/handlers/exception.py", line 57, in inner
    response = response_for_exception(request, exc)
               ^^^^^^^^^^^^^^^^^^^^^^^^^^^^^^^^^^^^
  File "/home/lighvzkx/virtualenv/max_app/3.11/lib/python3.11/site-packages/django/core/handlers/exception.py", line 140, in response_for_exception
    response = handle_uncaught_exception(
               ^^^^^^^^^^^^^^^^^^^^^^^^^^
  File "/home/lighvzkx/virtualenv/max_app/3.11/lib/python3.11/site-packages/django/core/handlers/exception.py", line 181, in handle_uncaught_exception
    return debug.technical_500_response(request, *exc_info)
           ^^^^^^^^^^^^^^^^^^^^^^^^^^^^^^^^^^^^^^^^^^^^^^^^
  File "/home/lighvzkx/virtualenv/max_app/3.11/lib/python3.11/site-packages/django/views/debug.py", line 67, in technical_500_response
    html = reporter.get_traceback_html()
           ^^^^^^^^^^^^^^^^^^^^^^^^^^^^^
  File "/home/lighvzkx/virtualenv/max_app/3.11/lib/python3.11/site-packages/django/views/debug.py", line 410, in get_traceback_html
    c = Context(self.get_traceback_data(), use_l10n=False)
                ^^^^^^^^^^^^^^^^^^^^^^^^^
  File "/home/lighvzkx/virtualenv/max_app/3.11/lib/python3.11/site-packages/django/views/debug.py", line 393, in get_traceback_data
    c["raising_view_name"] = get_caller(self.request)
                             ^^^^^^^^^^^^^^^^^^^^^^^^
  File "/home/lighvzkx/virtualenv/max_app/3.11/lib/python3.11/site-packages/django/views/debug.py", line 100, in get_caller
    resolver_match = resolve(request.path)
                     ^^^^^^^^^^^^^^^^^^^^^
  File "/home/lighvzkx/virtualenv/max_app/3.11/lib/python3.11/site-packages/django/urls/base.py", line 24, in resolve
    return get_resolver(urlconf).resolve(path)
           ^^^^^^^^^^^^^^^^^^^^^^^^^^^^^^^^^^^
  File "/home/lighvzkx/virtualenv/max_app/3.11/lib/python3.11/site-packages/django/urls/resolvers.py", line 663, in resolve
    for pattern in self.url_patterns:
                   ^^^^^^^^^^^^^^^^^
  File "/home/lighvzkx/virtualenv/max_app/3.11/lib/python3.11/site-packages/django/utils/functional.py", line 57, in __get__
    res = instance.__dict__[self.name] = self.func(instance)
                                         ^^^^^^^^^^^^^^^^^^^
  File "/home/lighvzkx/virtualenv/max_app/3.11/lib/python3.11/site-packages/django/urls/resolvers.py", line 715, in url_patterns
    patterns = getattr(self.urlconf_module, "urlpatterns", self.urlconf_module)
                       ^^^^^^^^^^^^^^^^^^^
  File "/home/lighvzkx/virtualenv/max_app/3.11/lib/python3.11/site-packages/django/utils/functional.py", line 57, in __get__
    res = instance.__dict__[self.name] = self.func(instance)
                                         ^^^^^^^^^^^^^^^^^^^
  File "/home/lighvzkx/virtualenv/max_app/3.11/lib/python3.11/site-packages/django/urls/resolvers.py", line 708, in urlconf_module
    return import_module(self.urlconf_name)
           ^^^^^^^^^^^^^^^^^^^^^^^^^^^^^^^^
  File "/opt/alt/python311/lib64/python3.11/importlib/__init__.py", line 126, in import_module
    return _bootstrap._gcd_import(name[level:], package, level)
           ^^^^^^^^^^^^^^^^^^^^^^^^^^^^^^^^^^^^^^^^^^^^^^^^^^^^
  File "<frozen importlib._bootstrap>", line 1204, in _gcd_import
  File "<frozen importlib._bootstrap>", line 1176, in _find_and_load
  File "<frozen importlib._bootstrap>", line 1147, in _find_and_load_unlocked
  File "<frozen importlib._bootstrap>", line 690, in _load_unlocked
  File "<frozen importlib._bootstrap_external>", line 940, in exec_module
  File "<frozen importlib._bootstrap>", line 241, in _call_with_frames_removed
  File "/home/lighvzkx/max_app/max_app_prooj/urls.py", line 22, in <module>
    path('', include('business.urls')),
             ^^^^^^^^^^^^^^^^^^^^^^^^
  File "/home/lighvzkx/virtualenv/max_app/3.11/lib/python3.11/site-packages/django/urls/conf.py", line 38, in include
    urlconf_module = import_module(urlconf_module)
                     ^^^^^^^^^^^^^^^^^^^^^^^^^^^^^
  File "/opt/alt/python311/lib64/python3.11/importlib/__init__.py", line 126, in import_module
    return _bootstrap._gcd_import(name[level:], package, level)
           ^^^^^^^^^^^^^^^^^^^^^^^^^^^^^^^^^^^^^^^^^^^^^^^^^^^^
  File "<frozen importlib._bootstrap>", line 1204, in _gcd_import
  File "<frozen importlib._bootstrap>", line 1176, in _find_and_load
  File "<frozen importlib._bootstrap>", line 1140, in _find_and_load_unlocked
ModuleNotFoundError: No module named 'business.urls'

During handling of the above exception, another exception occurred:

Traceback (most recent call last):
  File "/home/lighvzkx/virtualenv/max_app/3.11/lib/python3.11/site-packages/django/core/handlers/exception.py", line 55, in inner
    response = get_response(request)
               ^^^^^^^^^^^^^^^^^^^^^
  File "/home/lighvzkx/virtualenv/max_app/3.11/lib/python3.11/site-packages/django/utils/deprecation.py", line 134, in __call__
    response = response or self.get_response(request)
                           ^^^^^^^^^^^^^^^^^^^^^^^^^^
  File "/home/lighvzkx/virtualenv/max_app/3.11/lib/python3.11/site-packages/django/core/handlers/exception.py", line 57, in inner
    response = response_for_exception(request, exc)
               ^^^^^^^^^^^^^^^^^^^^^^^^^^^^^^^^^^^^
  File "/home/lighvzkx/virtualenv/max_app/3.11/lib/python3.11/site-packages/django/core/handlers/exception.py", line 140, in response_for_exception
    response = handle_uncaught_exception(
               ^^^^^^^^^^^^^^^^^^^^^^^^^^
  File "/home/lighvzkx/virtualenv/max_app/3.11/lib/python3.11/site-packages/django/core/handlers/exception.py", line 181, in handle_uncaught_exception
    return debug.technical_500_response(request, *exc_info)
           ^^^^^^^^^^^^^^^^^^^^^^^^^^^^^^^^^^^^^^^^^^^^^^^^
  File "/home/lighvzkx/virtualenv/max_app/3.11/lib/python3.11/site-packages/django/views/debug.py", line 67, in technical_500_response
    html = reporter.get_traceback_html()
           ^^^^^^^^^^^^^^^^^^^^^^^^^^^^^
  File "/home/lighvzkx/virtualenv/max_app/3.11/lib/python3.11/site-packages/django/views/debug.py", line 410, in get_traceback_html
    c = Context(self.get_traceback_data(), use_l10n=False)
                ^^^^^^^^^^^^^^^^^^^^^^^^^
  File "/home/lighvzkx/virtualenv/max_app/3.11/lib/python3.11/site-packages/django/views/debug.py", line 393, in get_traceback_data
    c["raising_view_name"] = get_caller(self.request)
                             ^^^^^^^^^^^^^^^^^^^^^^^^
  File "/home/lighvzkx/virtualenv/max_app/3.11/lib/python3.11/site-packages/django/views/debug.py", line 100, in get_caller
    resolver_match = resolve(request.path)
                     ^^^^^^^^^^^^^^^^^^^^^
  File "/home/lighvzkx/virtualenv/max_app/3.11/lib/python3.11/site-packages/django/urls/base.py", line 24, in resolve
    return get_resolver(urlconf).resolve(path)
           ^^^^^^^^^^^^^^^^^^^^^^^^^^^^^^^^^^^
  File "/home/lighvzkx/virtualenv/max_app/3.11/lib/python3.11/site-packages/django/urls/resolvers.py", line 663, in resolve
    for pattern in self.url_patterns:
                   ^^^^^^^^^^^^^^^^^
  File "/home/lighvzkx/virtualenv/max_app/3.11/lib/python3.11/site-packages/django/utils/functional.py", line 57, in __get__
    res = instance.__dict__[self.name] = self.func(instance)
                                         ^^^^^^^^^^^^^^^^^^^
  File "/home/lighvzkx/virtualenv/max_app/3.11/lib/python3.11/site-packages/django/urls/resolvers.py", line 715, in url_patterns
    patterns = getattr(self.urlconf_module, "urlpatterns", self.urlconf_module)
                       ^^^^^^^^^^^^^^^^^^^
  File "/home/lighvzkx/virtualenv/max_app/3.11/lib/python3.11/site-packages/django/utils/functional.py", line 57, in __get__
    res = instance.__dict__[self.name] = self.func(instance)
                                         ^^^^^^^^^^^^^^^^^^^
  File "/home/lighvzkx/virtualenv/max_app/3.11/lib/python3.11/site-packages/django/urls/resolvers.py", line 708, in urlconf_module
    return import_module(self.urlconf_name)
           ^^^^^^^^^^^^^^^^^^^^^^^^^^^^^^^^
  File "/opt/alt/python311/lib64/python3.11/importlib/__init__.py", line 126, in import_module
    return _bootstrap._gcd_import(name[level:], package, level)
           ^^^^^^^^^^^^^^^^^^^^^^^^^^^^^^^^^^^^^^^^^^^^^^^^^^^^
  File "<frozen importlib._bootstrap>", line 1204, in _gcd_import
  File "<frozen importlib._bootstrap>", line 1176, in _find_and_load
  File "<frozen importlib._bootstrap>", line 1147, in _find_and_load_unlocked
  File "<frozen importlib._bootstrap>", line 690, in _load_unlocked
  File "<frozen importlib._bootstrap_external>", line 940, in exec_module
  File "<frozen importlib._bootstrap>", line 241, in _call_with_frames_removed
  File "/home/lighvzkx/max_app/max_app_prooj/urls.py", line 22, in <module>
    path('', include('business.urls')),
             ^^^^^^^^^^^^^^^^^^^^^^^^
  File "/home/lighvzkx/virtualenv/max_app/3.11/lib/python3.11/site-packages/django/urls/conf.py", line 38, in include
    urlconf_module = import_module(urlconf_module)
                     ^^^^^^^^^^^^^^^^^^^^^^^^^^^^^
  File "/opt/alt/python311/lib64/python3.11/importlib/__init__.py", line 126, in import_module
    return _bootstrap._gcd_import(name[level:], package, level)
           ^^^^^^^^^^^^^^^^^^^^^^^^^^^^^^^^^^^^^^^^^^^^^^^^^^^^
  File "<frozen importlib._bootstrap>", line 1204, in _gcd_import
  File "<frozen importlib._bootstrap>", line 1176, in _find_and_load
  File "<frozen importlib._bootstrap>", line 1140, in _find_and_load_unlocked
ModuleNotFoundError: No module named 'business.urls'

During handling of the above exception, another exception occurred:

Traceback (most recent call last):
  File "/home/lighvzkx/virtualenv/max_app/3.11/lib/python3.11/site-packages/django/core/handlers/exception.py", line 55, in inner
    response = get_response(request)
               ^^^^^^^^^^^^^^^^^^^^^
  File "/home/lighvzkx/virtualenv/max_app/3.11/lib/python3.11/site-packages/django/utils/deprecation.py", line 134, in __call__
    response = response or self.get_response(request)
                           ^^^^^^^^^^^^^^^^^^^^^^^^^^
  File "/home/lighvzkx/virtualenv/max_app/3.11/lib/python3.11/site-packages/django/core/handlers/exception.py", line 57, in inner
    response = response_for_exception(request, exc)
               ^^^^^^^^^^^^^^^^^^^^^^^^^^^^^^^^^^^^
  File "/home/lighvzkx/virtualenv/max_app/3.11/lib/python3.11/site-packages/django/core/handlers/exception.py", line 140, in response_for_exception
    response = handle_uncaught_exception(
               ^^^^^^^^^^^^^^^^^^^^^^^^^^
  File "/home/lighvzkx/virtualenv/max_app/3.11/lib/python3.11/site-packages/django/core/handlers/exception.py", line 181, in handle_uncaught_exception
    return debug.technical_500_response(request, *exc_info)
           ^^^^^^^^^^^^^^^^^^^^^^^^^^^^^^^^^^^^^^^^^^^^^^^^
  File "/home/lighvzkx/virtualenv/max_app/3.11/lib/python3.11/site-packages/django/views/debug.py", line 67, in technical_500_response
    html = reporter.get_traceback_html()
           ^^^^^^^^^^^^^^^^^^^^^^^^^^^^^
  File "/home/lighvzkx/virtualenv/max_app/3.11/lib/python3.11/site-packages/django/views/debug.py", line 410, in get_traceback_html
    c = Context(self.get_traceback_data(), use_l10n=False)
                ^^^^^^^^^^^^^^^^^^^^^^^^^
  File "/home/lighvzkx/virtualenv/max_app/3.11/lib/python3.11/site-packages/django/views/debug.py", line 393, in get_traceback_data
    c["raising_view_name"] = get_caller(self.request)
                             ^^^^^^^^^^^^^^^^^^^^^^^^
  File "/home/lighvzkx/virtualenv/max_app/3.11/lib/python3.11/site-packages/django/views/debug.py", line 100, in get_caller
    resolver_match = resolve(request.path)
                     ^^^^^^^^^^^^^^^^^^^^^
  File "/home/lighvzkx/virtualenv/max_app/3.11/lib/python3.11/site-packages/django/urls/base.py", line 24, in resolve
    return get_resolver(urlconf).resolve(path)
           ^^^^^^^^^^^^^^^^^^^^^^^^^^^^^^^^^^^
  File "/home/lighvzkx/virtualenv/max_app/3.11/lib/python3.11/site-packages/django/urls/resolvers.py", line 663, in resolve
    for pattern in self.url_patterns:
                   ^^^^^^^^^^^^^^^^^
  File "/home/lighvzkx/virtualenv/max_app/3.11/lib/python3.11/site-packages/django/utils/functional.py", line 57, in __get__
    res = instance.__dict__[self.name] = self.func(instance)
                                         ^^^^^^^^^^^^^^^^^^^
  File "/home/lighvzkx/virtualenv/max_app/3.11/lib/python3.11/site-packages/django/urls/resolvers.py", line 715, in url_patterns
    patterns = getattr(self.urlconf_module, "urlpatterns", self.urlconf_module)
                       ^^^^^^^^^^^^^^^^^^^
  File "/home/lighvzkx/virtualenv/max_app/3.11/lib/python3.11/site-packages/django/utils/functional.py", line 57, in __get__
    res = instance.__dict__[self.name] = self.func(instance)
                                         ^^^^^^^^^^^^^^^^^^^
  File "/home/lighvzkx/virtualenv/max_app/3.11/lib/python3.11/site-packages/django/urls/resolvers.py", line 708, in urlconf_module
    return import_module(self.urlconf_name)
           ^^^^^^^^^^^^^^^^^^^^^^^^^^^^^^^^
  File "/opt/alt/python311/lib64/python3.11/importlib/__init__.py", line 126, in import_module
    return _bootstrap._gcd_import(name[level:], package, level)
           ^^^^^^^^^^^^^^^^^^^^^^^^^^^^^^^^^^^^^^^^^^^^^^^^^^^^
  File "<frozen importlib._bootstrap>", line 1204, in _gcd_import
  File "<frozen importlib._bootstrap>", line 1176, in _find_and_load
  File "<frozen importlib._bootstrap>", line 1147, in _find_and_load_unlocked
  File "<frozen importlib._bootstrap>", line 690, in _load_unlocked
  File "<frozen importlib._bootstrap_external>", line 940, in exec_module
  File "<frozen importlib._bootstrap>", line 241, in _call_with_frames_removed
  File "/home/lighvzkx/max_app/max_app_prooj/urls.py", line 22, in <module>
    path('', include('business.urls')),
             ^^^^^^^^^^^^^^^^^^^^^^^^
  File "/home/lighvzkx/virtualenv/max_app/3.11/lib/python3.11/site-packages/django/urls/conf.py", line 38, in include
    urlconf_module = import_module(urlconf_module)
                     ^^^^^^^^^^^^^^^^^^^^^^^^^^^^^
  File "/opt/alt/python311/lib64/python3.11/importlib/__init__.py", line 126, in import_module
    return _bootstrap._gcd_import(name[level:], package, level)
           ^^^^^^^^^^^^^^^^^^^^^^^^^^^^^^^^^^^^^^^^^^^^^^^^^^^^
  File "<frozen importlib._bootstrap>", line 1204, in _gcd_import
  File "<frozen importlib._bootstrap>", line 1176, in _find_and_load
  File "<frozen importlib._bootstrap>", line 1140, in _find_and_load_unlocked
ModuleNotFoundError: No module named 'business.urls'

During handling of the above exception, another exception occurred:

Traceback (most recent call last):
  File "/home/lighvzkx/virtualenv/max_app/3.11/lib/python3.11/site-packages/django/core/handlers/exception.py", line 55, in inner
    response = get_response(request)
               ^^^^^^^^^^^^^^^^^^^^^
  File "/home/lighvzkx/virtualenv/max_app/3.11/lib/python3.11/site-packages/django/utils/deprecation.py", line 134, in __call__
    response = response or self.get_response(request)
                           ^^^^^^^^^^^^^^^^^^^^^^^^^^
  File "/home/lighvzkx/virtualenv/max_app/3.11/lib/python3.11/site-packages/django/core/handlers/exception.py", line 57, in inner
    response = response_for_exception(request, exc)
               ^^^^^^^^^^^^^^^^^^^^^^^^^^^^^^^^^^^^
  File "/home/lighvzkx/virtualenv/max_app/3.11/lib/python3.11/site-packages/django/core/handlers/exception.py", line 140, in response_for_exception
    response = handle_uncaught_exception(
               ^^^^^^^^^^^^^^^^^^^^^^^^^^
  File "/home/lighvzkx/virtualenv/max_app/3.11/lib/python3.11/site-packages/django/core/handlers/exception.py", line 181, in handle_uncaught_exception
    return debug.technical_500_response(request, *exc_info)
           ^^^^^^^^^^^^^^^^^^^^^^^^^^^^^^^^^^^^^^^^^^^^^^^^
  File "/home/lighvzkx/virtualenv/max_app/3.11/lib/python3.11/site-packages/django/views/debug.py", line 67, in technical_500_response
    html = reporter.get_traceback_html()
           ^^^^^^^^^^^^^^^^^^^^^^^^^^^^^
  File "/home/lighvzkx/virtualenv/max_app/3.11/lib/python3.11/site-packages/django/views/debug.py", line 410, in get_traceback_html
    c = Context(self.get_traceback_data(), use_l10n=False)
                ^^^^^^^^^^^^^^^^^^^^^^^^^
  File "/home/lighvzkx/virtualenv/max_app/3.11/lib/python3.11/site-packages/django/views/debug.py", line 393, in get_traceback_data
    c["raising_view_name"] = get_caller(self.request)
                             ^^^^^^^^^^^^^^^^^^^^^^^^
  File "/home/lighvzkx/virtualenv/max_app/3.11/lib/python3.11/site-packages/django/views/debug.py", line 100, in get_caller
    resolver_match = resolve(request.path)
                     ^^^^^^^^^^^^^^^^^^^^^
  File "/home/lighvzkx/virtualenv/max_app/3.11/lib/python3.11/site-packages/django/urls/base.py", line 24, in resolve
    return get_resolver(urlconf).resolve(path)
           ^^^^^^^^^^^^^^^^^^^^^^^^^^^^^^^^^^^
  File "/home/lighvzkx/virtualenv/max_app/3.11/lib/python3.11/site-packages/django/urls/resolvers.py", line 663, in resolve
    for pattern in self.url_patterns:
                   ^^^^^^^^^^^^^^^^^
  File "/home/lighvzkx/virtualenv/max_app/3.11/lib/python3.11/site-packages/django/utils/functional.py", line 57, in __get__
    res = instance.__dict__[self.name] = self.func(instance)
                                         ^^^^^^^^^^^^^^^^^^^
  File "/home/lighvzkx/virtualenv/max_app/3.11/lib/python3.11/site-packages/django/urls/resolvers.py", line 715, in url_patterns
    patterns = getattr(self.urlconf_module, "urlpatterns", self.urlconf_module)
                       ^^^^^^^^^^^^^^^^^^^
  File "/home/lighvzkx/virtualenv/max_app/3.11/lib/python3.11/site-packages/django/utils/functional.py", line 57, in __get__
    res = instance.__dict__[self.name] = self.func(instance)
                                         ^^^^^^^^^^^^^^^^^^^
  File "/home/lighvzkx/virtualenv/max_app/3.11/lib/python3.11/site-packages/django/urls/resolvers.py", line 708, in urlconf_module
    return import_module(self.urlconf_name)
           ^^^^^^^^^^^^^^^^^^^^^^^^^^^^^^^^
  File "/opt/alt/python311/lib64/python3.11/importlib/__init__.py", line 126, in import_module
    return _bootstrap._gcd_import(name[level:], package, level)
           ^^^^^^^^^^^^^^^^^^^^^^^^^^^^^^^^^^^^^^^^^^^^^^^^^^^^
  File "<frozen importlib._bootstrap>", line 1204, in _gcd_import
  File "<frozen importlib._bootstrap>", line 1176, in _find_and_load
  File "<frozen importlib._bootstrap>", line 1147, in _find_and_load_unlocked
  File "<frozen importlib._bootstrap>", line 690, in _load_unlocked
  File "<frozen importlib._bootstrap_external>", line 940, in exec_module
  File "<frozen importlib._bootstrap>", line 241, in _call_with_frames_removed
  File "/home/lighvzkx/max_app/max_app_prooj/urls.py", line 22, in <module>
    path('', include('business.urls')),
             ^^^^^^^^^^^^^^^^^^^^^^^^
  File "/home/lighvzkx/virtualenv/max_app/3.11/lib/python3.11/site-packages/django/urls/conf.py", line 38, in include
    urlconf_module = import_module(urlconf_module)
                     ^^^^^^^^^^^^^^^^^^^^^^^^^^^^^
  File "/opt/alt/python311/lib64/python3.11/importlib/__init__.py", line 126, in import_module
    return _bootstrap._gcd_import(name[level:], package, level)
           ^^^^^^^^^^^^^^^^^^^^^^^^^^^^^^^^^^^^^^^^^^^^^^^^^^^^
  File "<frozen importlib._bootstrap>", line 1204, in _gcd_import
  File "<frozen importlib._bootstrap>", line 1176, in _find_and_load
  File "<frozen importlib._bootstrap>", line 1140, in _find_and_load_unlocked
ModuleNotFoundError: No module named 'business.urls'

During handling of the above exception, another exception occurred:

Traceback (most recent call last):
  File "/home/lighvzkx/virtualenv/max_app/3.11/lib/python3.11/site-packages/django/core/handlers/exception.py", line 55, in inner
    response = get_response(request)
               ^^^^^^^^^^^^^^^^^^^^^
  File "/home/lighvzkx/virtualenv/max_app/3.11/lib/python3.11/site-packages/django/utils/deprecation.py", line 134, in __call__
    response = response or self.get_response(request)
                           ^^^^^^^^^^^^^^^^^^^^^^^^^^
  File "/home/lighvzkx/virtualenv/max_app/3.11/lib/python3.11/site-packages/django/core/handlers/exception.py", line 57, in inner
    response = response_for_exception(request, exc)
               ^^^^^^^^^^^^^^^^^^^^^^^^^^^^^^^^^^^^
  File "/home/lighvzkx/virtualenv/max_app/3.11/lib/python3.11/site-packages/django/core/handlers/exception.py", line 140, in response_for_exception
    response = handle_uncaught_exception(
               ^^^^^^^^^^^^^^^^^^^^^^^^^^
  File "/home/lighvzkx/virtualenv/max_app/3.11/lib/python3.11/site-packages/django/core/handlers/exception.py", line 181, in handle_uncaught_exception
    return debug.technical_500_response(request, *exc_info)
           ^^^^^^^^^^^^^^^^^^^^^^^^^^^^^^^^^^^^^^^^^^^^^^^^
  File "/home/lighvzkx/virtualenv/max_app/3.11/lib/python3.11/site-packages/django/views/debug.py", line 67, in technical_500_response
    html = reporter.get_traceback_html()
           ^^^^^^^^^^^^^^^^^^^^^^^^^^^^^
  File "/home/lighvzkx/virtualenv/max_app/3.11/lib/python3.11/site-packages/django/views/debug.py", line 410, in get_traceback_html
    c = Context(self.get_traceback_data(), use_l10n=False)
                ^^^^^^^^^^^^^^^^^^^^^^^^^
  File "/home/lighvzkx/virtualenv/max_app/3.11/lib/python3.11/site-packages/django/views/debug.py", line 393, in get_traceback_data
    c["raising_view_name"] = get_caller(self.request)
                             ^^^^^^^^^^^^^^^^^^^^^^^^
  File "/home/lighvzkx/virtualenv/max_app/3.11/lib/python3.11/site-packages/django/views/debug.py", line 100, in get_caller
    resolver_match = resolve(request.path)
                     ^^^^^^^^^^^^^^^^^^^^^
  File "/home/lighvzkx/virtualenv/max_app/3.11/lib/python3.11/site-packages/django/urls/base.py", line 24, in resolve
    return get_resolver(urlconf).resolve(path)
           ^^^^^^^^^^^^^^^^^^^^^^^^^^^^^^^^^^^
  File "/home/lighvzkx/virtualenv/max_app/3.11/lib/python3.11/site-packages/django/urls/resolvers.py", line 663, in resolve
    for pattern in self.url_patterns:
                   ^^^^^^^^^^^^^^^^^
  File "/home/lighvzkx/virtualenv/max_app/3.11/lib/python3.11/site-packages/django/utils/functional.py", line 57, in __get__
    res = instance.__dict__[self.name] = self.func(instance)
                                         ^^^^^^^^^^^^^^^^^^^
  File "/home/lighvzkx/virtualenv/max_app/3.11/lib/python3.11/site-packages/django/urls/resolvers.py", line 715, in url_patterns
    patterns = getattr(self.urlconf_module, "urlpatterns", self.urlconf_module)
                       ^^^^^^^^^^^^^^^^^^^
  File "/home/lighvzkx/virtualenv/max_app/3.11/lib/python3.11/site-packages/django/utils/functional.py", line 57, in __get__
    res = instance.__dict__[self.name] = self.func(instance)
                                         ^^^^^^^^^^^^^^^^^^^
  File "/home/lighvzkx/virtualenv/max_app/3.11/lib/python3.11/site-packages/django/urls/resolvers.py", line 708, in urlconf_module
    return import_module(self.urlconf_name)
           ^^^^^^^^^^^^^^^^^^^^^^^^^^^^^^^^
  File "/opt/alt/python311/lib64/python3.11/importlib/__init__.py", line 126, in import_module
    return _bootstrap._gcd_import(name[level:], package, level)
           ^^^^^^^^^^^^^^^^^^^^^^^^^^^^^^^^^^^^^^^^^^^^^^^^^^^^
  File "<frozen importlib._bootstrap>", line 1204, in _gcd_import
  File "<frozen importlib._bootstrap>", line 1176, in _find_and_load
  File "<frozen importlib._bootstrap>", line 1147, in _find_and_load_unlocked
  File "<frozen importlib._bootstrap>", line 690, in _load_unlocked
  File "<frozen importlib._bootstrap_external>", line 940, in exec_module
  File "<frozen importlib._bootstrap>", line 241, in _call_with_frames_removed
  File "/home/lighvzkx/max_app/max_app_prooj/urls.py", line 22, in <module>
    path('', include('business.urls')),
             ^^^^^^^^^^^^^^^^^^^^^^^^
  File "/home/lighvzkx/virtualenv/max_app/3.11/lib/python3.11/site-packages/django/urls/conf.py", line 38, in include
    urlconf_module = import_module(urlconf_module)
                     ^^^^^^^^^^^^^^^^^^^^^^^^^^^^^
  File "/opt/alt/python311/lib64/python3.11/importlib/__init__.py", line 126, in import_module
    return _bootstrap._gcd_import(name[level:], package, level)
           ^^^^^^^^^^^^^^^^^^^^^^^^^^^^^^^^^^^^^^^^^^^^^^^^^^^^
  File "<frozen importlib._bootstrap>", line 1204, in _gcd_import
  File "<frozen importlib._bootstrap>", line 1176, in _find_and_load
  File "<frozen importlib._bootstrap>", line 1140, in _find_and_load_unlocked
ModuleNotFoundError: No module named 'business.urls'

During handling of the above exception, another exception occurred:

Traceback (most recent call last):
  File "/home/lighvzkx/virtualenv/max_app/3.11/lib/python3.11/site-packages/django/core/handlers/exception.py", line 55, in inner
    response = get_response(request)
               ^^^^^^^^^^^^^^^^^^^^^
  File "/home/lighvzkx/virtualenv/max_app/3.11/lib/python3.11/site-packages/django/utils/deprecation.py", line 134, in __call__
    response = response or self.get_response(request)
                           ^^^^^^^^^^^^^^^^^^^^^^^^^^
  File "/home/lighvzkx/virtualenv/max_app/3.11/lib/python3.11/site-packages/django/core/handlers/exception.py", line 57, in inner
    response = response_for_exception(request, exc)
               ^^^^^^^^^^^^^^^^^^^^^^^^^^^^^^^^^^^^
  File "/home/lighvzkx/virtualenv/max_app/3.11/lib/python3.11/site-packages/django/core/handlers/exception.py", line 140, in response_for_exception
    response = handle_uncaught_exception(
               ^^^^^^^^^^^^^^^^^^^^^^^^^^
  File "/home/lighvzkx/virtualenv/max_app/3.11/lib/python3.11/site-packages/django/core/handlers/exception.py", line 181, in handle_uncaught_exception
    return debug.technical_500_response(request, *exc_info)
           ^^^^^^^^^^^^^^^^^^^^^^^^^^^^^^^^^^^^^^^^^^^^^^^^
  File "/home/lighvzkx/virtualenv/max_app/3.11/lib/python3.11/site-packages/django/views/debug.py", line 67, in technical_500_response
    html = reporter.get_traceback_html()
           ^^^^^^^^^^^^^^^^^^^^^^^^^^^^^
  File "/home/lighvzkx/virtualenv/max_app/3.11/lib/python3.11/site-packages/django/views/debug.py", line 410, in get_traceback_html
    c = Context(self.get_traceback_data(), use_l10n=False)
                ^^^^^^^^^^^^^^^^^^^^^^^^^
  File "/home/lighvzkx/virtualenv/max_app/3.11/lib/python3.11/site-packages/django/views/debug.py", line 393, in get_traceback_data
    c["raising_view_name"] = get_caller(self.request)
                             ^^^^^^^^^^^^^^^^^^^^^^^^
  File "/home/lighvzkx/virtualenv/max_app/3.11/lib/python3.11/site-packages/django/views/debug.py", line 100, in get_caller
    resolver_match = resolve(request.path)
                     ^^^^^^^^^^^^^^^^^^^^^
  File "/home/lighvzkx/virtualenv/max_app/3.11/lib/python3.11/site-packages/django/urls/base.py", line 24, in resolve
    return get_resolver(urlconf).resolve(path)
           ^^^^^^^^^^^^^^^^^^^^^^^^^^^^^^^^^^^
  File "/home/lighvzkx/virtualenv/max_app/3.11/lib/python3.11/site-packages/django/urls/resolvers.py", line 663, in resolve
    for pattern in self.url_patterns:
                   ^^^^^^^^^^^^^^^^^
  File "/home/lighvzkx/virtualenv/max_app/3.11/lib/python3.11/site-packages/django/utils/functional.py", line 57, in __get__
    res = instance.__dict__[self.name] = self.func(instance)
                                         ^^^^^^^^^^^^^^^^^^^
  File "/home/lighvzkx/virtualenv/max_app/3.11/lib/python3.11/site-packages/django/urls/resolvers.py", line 715, in url_patterns
    patterns = getattr(self.urlconf_module, "urlpatterns", self.urlconf_module)
                       ^^^^^^^^^^^^^^^^^^^
  File "/home/lighvzkx/virtualenv/max_app/3.11/lib/python3.11/site-packages/django/utils/functional.py", line 57, in __get__
    res = instance.__dict__[self.name] = self.func(instance)
                                         ^^^^^^^^^^^^^^^^^^^
  File "/home/lighvzkx/virtualenv/max_app/3.11/lib/python3.11/site-packages/django/urls/resolvers.py", line 708, in urlconf_module
    return import_module(self.urlconf_name)
           ^^^^^^^^^^^^^^^^^^^^^^^^^^^^^^^^
  File "/opt/alt/python311/lib64/python3.11/importlib/__init__.py", line 126, in import_module
    return _bootstrap._gcd_import(name[level:], package, level)
           ^^^^^^^^^^^^^^^^^^^^^^^^^^^^^^^^^^^^^^^^^^^^^^^^^^^^
  File "<frozen importlib._bootstrap>", line 1204, in _gcd_import
  File "<frozen importlib._bootstrap>", line 1176, in _find_and_load
  File "<frozen importlib._bootstrap>", line 1147, in _find_and_load_unlocked
  File "<frozen importlib._bootstrap>", line 690, in _load_unlocked
  File "<frozen importlib._bootstrap_external>", line 940, in exec_module
  File "<frozen importlib._bootstrap>", line 241, in _call_with_frames_removed
  File "/home/lighvzkx/max_app/max_app_prooj/urls.py", line 22, in <module>
    path('', include('business.urls')),
             ^^^^^^^^^^^^^^^^^^^^^^^^
  File "/home/lighvzkx/virtualenv/max_app/3.11/lib/python3.11/site-packages/django/urls/conf.py", line 38, in include
    urlconf_module = import_module(urlconf_module)
                     ^^^^^^^^^^^^^^^^^^^^^^^^^^^^^
  File "/opt/alt/python311/lib64/python3.11/importlib/__init__.py", line 126, in import_module
    return _bootstrap._gcd_import(name[level:], package, level)
           ^^^^^^^^^^^^^^^^^^^^^^^^^^^^^^^^^^^^^^^^^^^^^^^^^^^^
  File "<frozen importlib._bootstrap>", line 1204, in _gcd_import
  File "<frozen importlib._bootstrap>", line 1176, in _find_and_load
  File "<frozen importlib._bootstrap>", line 1140, in _find_and_load_unlocked
ModuleNotFoundError: No module named 'business.urls'

During handling of the above exception, another exception occurred:

Traceback (most recent call last):
  File "/home/lighvzkx/virtualenv/max_app/3.11/lib/python3.11/site-packages/django/core/handlers/wsgi.py", line 124, in __call__
    response = self.get_response(request)
               ^^^^^^^^^^^^^^^^^^^^^^^^^^
  File "/home/lighvzkx/virtualenv/max_app/3.11/lib/python3.11/site-packages/django/core/handlers/base.py", line 140, in get_response
    response = self._middleware_chain(request)
               ^^^^^^^^^^^^^^^^^^^^^^^^^^^^^^^
  File "/home/lighvzkx/virtualenv/max_app/3.11/lib/python3.11/site-packages/django/core/handlers/exception.py", line 57, in inner
    response = response_for_exception(request, exc)
               ^^^^^^^^^^^^^^^^^^^^^^^^^^^^^^^^^^^^
  File "/home/lighvzkx/virtualenv/max_app/3.11/lib/python3.11/site-packages/django/core/handlers/exception.py", line 140, in response_for_exception
    response = handle_uncaught_exception(
               ^^^^^^^^^^^^^^^^^^^^^^^^^^
  File "/home/lighvzkx/virtualenv/max_app/3.11/lib/python3.11/site-packages/django/core/handlers/exception.py", line 181, in handle_uncaught_exception
    return debug.technical_500_response(request, *exc_info)
           ^^^^^^^^^^^^^^^^^^^^^^^^^^^^^^^^^^^^^^^^^^^^^^^^
  File "/home/lighvzkx/virtualenv/max_app/3.11/lib/python3.11/site-packages/django/views/debug.py", line 67, in technical_500_response
    html = reporter.get_traceback_html()
           ^^^^^^^^^^^^^^^^^^^^^^^^^^^^^
  File "/home/lighvzkx/virtualenv/max_app/3.11/lib/python3.11/site-packages/django/views/debug.py", line 410, in get_traceback_html
    c = Context(self.get_traceback_data(), use_l10n=False)
                ^^^^^^^^^^^^^^^^^^^^^^^^^
  File "/home/lighvzkx/virtualenv/max_app/3.11/lib/python3.11/site-packages/django/views/debug.py", line 393, in get_traceback_data
    c["raising_view_name"] = get_caller(self.request)
                             ^^^^^^^^^^^^^^^^^^^^^^^^
  File "/home/lighvzkx/virtualenv/max_app/3.11/lib/python3.11/site-packages/django/views/debug.py", line 100, in get_caller
    resolver_match = resolve(request.path)
                     ^^^^^^^^^^^^^^^^^^^^^
  File "/home/lighvzkx/virtualenv/max_app/3.11/lib/python3.11/site-packages/django/urls/base.py", line 24, in resolve
    return get_resolver(urlconf).resolve(path)
           ^^^^^^^^^^^^^^^^^^^^^^^^^^^^^^^^^^^
  File "/home/lighvzkx/virtualenv/max_app/3.11/lib/python3.11/site-packages/django/urls/resolvers.py", line 663, in resolve
    for pattern in self.url_patterns:
                   ^^^^^^^^^^^^^^^^^
  File "/home/lighvzkx/virtualenv/max_app/3.11/lib/python3.11/site-packages/django/utils/functional.py", line 57, in __get__
    res = instance.__dict__[self.name] = self.func(instance)
                                         ^^^^^^^^^^^^^^^^^^^
  File "/home/lighvzkx/virtualenv/max_app/3.11/lib/python3.11/site-packages/django/urls/resolvers.py", line 715, in url_patterns
    patterns = getattr(self.urlconf_module, "urlpatterns", self.urlconf_module)
                       ^^^^^^^^^^^^^^^^^^^
  File "/home/lighvzkx/virtualenv/max_app/3.11/lib/python3.11/site-packages/django/utils/functional.py", line 57, in __get__
    res = instance.__dict__[self.name] = self.func(instance)
                                         ^^^^^^^^^^^^^^^^^^^
  File "/home/lighvzkx/virtualenv/max_app/3.11/lib/python3.11/site-packages/django/urls/resolvers.py", line 708, in urlconf_module
    return import_module(self.urlconf_name)
           ^^^^^^^^^^^^^^^^^^^^^^^^^^^^^^^^
  File "/opt/alt/python311/lib64/python3.11/importlib/__init__.py", line 126, in import_module
    return _bootstrap._gcd_import(name[level:], package, level)
           ^^^^^^^^^^^^^^^^^^^^^^^^^^^^^^^^^^^^^^^^^^^^^^^^^^^^
  File "<frozen importlib._bootstrap>", line 1204, in _gcd_import
  File "<frozen importlib._bootstrap>", line 1176, in _find_and_load
  File "<frozen importlib._bootstrap>", line 1147, in _find_and_load_unlocked
  File "<frozen importlib._bootstrap>", line 690, in _load_unlocked
  File "<frozen importlib._bootstrap_external>", line 940, in exec_module
  File "<frozen importlib._bootstrap>", line 241, in _call_with_frames_removed
  File "/home/lighvzkx/max_app/max_app_prooj/urls.py", line 22, in <module>
    path('', include('business.urls')),
             ^^^^^^^^^^^^^^^^^^^^^^^^
  File "/home/lighvzkx/virtualenv/max_app/3.11/lib/python3.11/site-packages/django/urls/conf.py", line 38, in include
    urlconf_module = import_module(urlconf_module)
                     ^^^^^^^^^^^^^^^^^^^^^^^^^^^^^
  File "/opt/alt/python311/lib64/python3.11/importlib/__init__.py", line 126, in import_module
    return _bootstrap._gcd_import(name[level:], package, level)
           ^^^^^^^^^^^^^^^^^^^^^^^^^^^^^^^^^^^^^^^^^^^^^^^^^^^^
  File "<frozen importlib._bootstrap>", line 1204, in _gcd_import
  File "<frozen importlib._bootstrap>", line 1176, in _find_and_load
  File "<frozen importlib._bootstrap>", line 1140, in _find_and_load_unlocked
ModuleNotFoundError: No module named 'business.urls'
[ERROR] [UID:13895][2358] wsgiAppHandler pApp->start_response() return NULL.
Traceback (most recent call last):
  File "/home/lighvzkx/virtualenv/max_app/3.11/lib/python3.11/site-packages/django/urls/resolvers.py", line 717, in url_patterns
    iter(patterns)
TypeError: 'module' object is not iterable

The above exception was the direct cause of the following exception:

Traceback (most recent call last):
  File "/home/lighvzkx/virtualenv/max_app/3.11/lib/python3.11/site-packages/django/core/handlers/exception.py", line 55, in inner
    response = get_response(request)
               ^^^^^^^^^^^^^^^^^^^^^
  File "/home/lighvzkx/virtualenv/max_app/3.11/lib/python3.11/site-packages/django/core/handlers/base.py", line 181, in _get_response
    callback, callback_args, callback_kwargs = self.resolve_request(request)
                                               ^^^^^^^^^^^^^^^^^^^^^^^^^^^^^
  File "/home/lighvzkx/virtualenv/max_app/3.11/lib/python3.11/site-packages/django/core/handlers/base.py", line 313, in resolve_request
    resolver_match = resolver.resolve(request.path_info)
                     ^^^^^^^^^^^^^^^^^^^^^^^^^^^^^^^^^^^
  File "/home/lighvzkx/virtualenv/max_app/3.11/lib/python3.11/site-packages/django/urls/resolvers.py", line 665, in resolve
    sub_match = pattern.resolve(new_path)
                ^^^^^^^^^^^^^^^^^^^^^^^^^
  File "/home/lighvzkx/virtualenv/max_app/3.11/lib/python3.11/site-packages/django/urls/resolvers.py", line 663, in resolve
    for pattern in self.url_patterns:
                   ^^^^^^^^^^^^^^^^^
  File "/home/lighvzkx/virtualenv/max_app/3.11/lib/python3.11/site-packages/django/utils/functional.py", line 57, in __get__
    res = instance.__dict__[self.name] = self.func(instance)
                                         ^^^^^^^^^^^^^^^^^^^
  File "/home/lighvzkx/virtualenv/max_app/3.11/lib/python3.11/site-packages/django/urls/resolvers.py", line 725, in url_patterns
    raise ImproperlyConfigured(msg.format(name=self.urlconf_name)) from e
django.core.exceptions.ImproperlyConfigured: The included URLconf '<module 'business.urls' from '/home/lighvzkx/max_app/business/urls.py'>' does not appear to have any patterns in it. If you see the 'urlpatterns' variable with valid patterns in the file then the issue is probably caused by a circular import.

During handling of the above exception, another exception occurred:

Traceback (most recent call last):
  File "/home/lighvzkx/virtualenv/max_app/3.11/lib/python3.11/site-packages/django/urls/resolvers.py", line 717, in url_patterns
    iter(patterns)
TypeError: 'module' object is not iterable

The above exception was the direct cause of the following exception:

Traceback (most recent call last):
  File "/home/lighvzkx/virtualenv/max_app/3.11/lib/python3.11/site-packages/django/core/handlers/exception.py", line 55, in inner
    response = get_response(request)
               ^^^^^^^^^^^^^^^^^^^^^
  File "/home/lighvzkx/virtualenv/max_app/3.11/lib/python3.11/site-packages/django/utils/deprecation.py", line 134, in __call__
    response = response or self.get_response(request)
                           ^^^^^^^^^^^^^^^^^^^^^^^^^^
  File "/home/lighvzkx/virtualenv/max_app/3.11/lib/python3.11/site-packages/django/core/handlers/exception.py", line 57, in inner
    response = response_for_exception(request, exc)
               ^^^^^^^^^^^^^^^^^^^^^^^^^^^^^^^^^^^^
  File "/home/lighvzkx/virtualenv/max_app/3.11/lib/python3.11/site-packages/django/core/handlers/exception.py", line 140, in response_for_exception
    response = handle_uncaught_exception(
               ^^^^^^^^^^^^^^^^^^^^^^^^^^
  File "/home/lighvzkx/virtualenv/max_app/3.11/lib/python3.11/site-packages/django/core/handlers/exception.py", line 181, in handle_uncaught_exception
    return debug.technical_500_response(request, *exc_info)
           ^^^^^^^^^^^^^^^^^^^^^^^^^^^^^^^^^^^^^^^^^^^^^^^^
  File "/home/lighvzkx/virtualenv/max_app/3.11/lib/python3.11/site-packages/django/views/debug.py", line 67, in technical_500_response
    html = reporter.get_traceback_html()
           ^^^^^^^^^^^^^^^^^^^^^^^^^^^^^
  File "/home/lighvzkx/virtualenv/max_app/3.11/lib/python3.11/site-packages/django/views/debug.py", line 410, in get_traceback_html
    c = Context(self.get_traceback_data(), use_l10n=False)
                ^^^^^^^^^^^^^^^^^^^^^^^^^
  File "/home/lighvzkx/virtualenv/max_app/3.11/lib/python3.11/site-packages/django/views/debug.py", line 393, in get_traceback_data
    c["raising_view_name"] = get_caller(self.request)
                             ^^^^^^^^^^^^^^^^^^^^^^^^
  File "/home/lighvzkx/virtualenv/max_app/3.11/lib/python3.11/site-packages/django/views/debug.py", line 100, in get_caller
    resolver_match = resolve(request.path)
                     ^^^^^^^^^^^^^^^^^^^^^
  File "/home/lighvzkx/virtualenv/max_app/3.11/lib/python3.11/site-packages/django/urls/base.py", line 24, in resolve
    return get_resolver(urlconf).resolve(path)
           ^^^^^^^^^^^^^^^^^^^^^^^^^^^^^^^^^^^
  File "/home/lighvzkx/virtualenv/max_app/3.11/lib/python3.11/site-packages/django/urls/resolvers.py", line 665, in resolve
    sub_match = pattern.resolve(new_path)
                ^^^^^^^^^^^^^^^^^^^^^^^^^
  File "/home/lighvzkx/virtualenv/max_app/3.11/lib/python3.11/site-packages/django/urls/resolvers.py", line 663, in resolve
    for pattern in self.url_patterns:
                   ^^^^^^^^^^^^^^^^^
  File "/home/lighvzkx/virtualenv/max_app/3.11/lib/python3.11/site-packages/django/utils/functional.py", line 57, in __get__
    res = instance.__dict__[self.name] = self.func(instance)
                                         ^^^^^^^^^^^^^^^^^^^
  File "/home/lighvzkx/virtualenv/max_app/3.11/lib/python3.11/site-packages/django/urls/resolvers.py", line 725, in url_patterns
    raise ImproperlyConfigured(msg.format(name=self.urlconf_name)) from e
django.core.exceptions.ImproperlyConfigured: The included URLconf '<module 'business.urls' from '/home/lighvzkx/max_app/business/urls.py'>' does not appear to have any patterns in it. If you see the 'urlpatterns' variable with valid patterns in the file then the issue is probably caused by a circular import.

During handling of the above exception, another exception occurred:

Traceback (most recent call last):
  File "/home/lighvzkx/virtualenv/max_app/3.11/lib/python3.11/site-packages/django/urls/resolvers.py", line 717, in url_patterns
    iter(patterns)
TypeError: 'module' object is not iterable

The above exception was the direct cause of the following exception:

Traceback (most recent call last):
  File "/home/lighvzkx/virtualenv/max_app/3.11/lib/python3.11/site-packages/django/core/handlers/exception.py", line 55, in inner
    response = get_response(request)
               ^^^^^^^^^^^^^^^^^^^^^
  File "/home/lighvzkx/virtualenv/max_app/3.11/lib/python3.11/site-packages/django/utils/deprecation.py", line 134, in __call__
    response = response or self.get_response(request)
                           ^^^^^^^^^^^^^^^^^^^^^^^^^^
  File "/home/lighvzkx/virtualenv/max_app/3.11/lib/python3.11/site-packages/django/core/handlers/exception.py", line 57, in inner
    response = response_for_exception(request, exc)
               ^^^^^^^^^^^^^^^^^^^^^^^^^^^^^^^^^^^^
  File "/home/lighvzkx/virtualenv/max_app/3.11/lib/python3.11/site-packages/django/core/handlers/exception.py", line 140, in response_for_exception
    response = handle_uncaught_exception(
               ^^^^^^^^^^^^^^^^^^^^^^^^^^
  File "/home/lighvzkx/virtualenv/max_app/3.11/lib/python3.11/site-packages/django/core/handlers/exception.py", line 181, in handle_uncaught_exception
    return debug.technical_500_response(request, *exc_info)
           ^^^^^^^^^^^^^^^^^^^^^^^^^^^^^^^^^^^^^^^^^^^^^^^^
  File "/home/lighvzkx/virtualenv/max_app/3.11/lib/python3.11/site-packages/django/views/debug.py", line 67, in technical_500_response
    html = reporter.get_traceback_html()
           ^^^^^^^^^^^^^^^^^^^^^^^^^^^^^
  File "/home/lighvzkx/virtualenv/max_app/3.11/lib/python3.11/site-packages/django/views/debug.py", line 410, in get_traceback_html
    c = Context(self.get_traceback_data(), use_l10n=False)
                ^^^^^^^^^^^^^^^^^^^^^^^^^
  File "/home/lighvzkx/virtualenv/max_app/3.11/lib/python3.11/site-packages/django/views/debug.py", line 393, in get_traceback_data
    c["raising_view_name"] = get_caller(self.request)
                             ^^^^^^^^^^^^^^^^^^^^^^^^
  File "/home/lighvzkx/virtualenv/max_app/3.11/lib/python3.11/site-packages/django/views/debug.py", line 100, in get_caller
    resolver_match = resolve(request.path)
                     ^^^^^^^^^^^^^^^^^^^^^
  File "/home/lighvzkx/virtualenv/max_app/3.11/lib/python3.11/site-packages/django/urls/base.py", line 24, in resolve
    return get_resolver(urlconf).resolve(path)
           ^^^^^^^^^^^^^^^^^^^^^^^^^^^^^^^^^^^
  File "/home/lighvzkx/virtualenv/max_app/3.11/lib/python3.11/site-packages/django/urls/resolvers.py", line 665, in resolve
    sub_match = pattern.resolve(new_path)
                ^^^^^^^^^^^^^^^^^^^^^^^^^
  File "/home/lighvzkx/virtualenv/max_app/3.11/lib/python3.11/site-packages/django/urls/resolvers.py", line 663, in resolve
    for pattern in self.url_patterns:
                   ^^^^^^^^^^^^^^^^^
  File "/home/lighvzkx/virtualenv/max_app/3.11/lib/python3.11/site-packages/django/utils/functional.py", line 57, in __get__
    res = instance.__dict__[self.name] = self.func(instance)
                                         ^^^^^^^^^^^^^^^^^^^
  File "/home/lighvzkx/virtualenv/max_app/3.11/lib/python3.11/site-packages/django/urls/resolvers.py", line 725, in url_patterns
    raise ImproperlyConfigured(msg.format(name=self.urlconf_name)) from e
django.core.exceptions.ImproperlyConfigured: The included URLconf '<module 'business.urls' from '/home/lighvzkx/max_app/business/urls.py'>' does not appear to have any patterns in it. If you see the 'urlpatterns' variable with valid patterns in the file then the issue is probably caused by a circular import.

During handling of the above exception, another exception occurred:

Traceback (most recent call last):
  File "/home/lighvzkx/virtualenv/max_app/3.11/lib/python3.11/site-packages/django/urls/resolvers.py", line 717, in url_patterns
    iter(patterns)
TypeError: 'module' object is not iterable

The above exception was the direct cause of the following exception:

Traceback (most recent call last):
  File "/home/lighvzkx/virtualenv/max_app/3.11/lib/python3.11/site-packages/django/core/handlers/exception.py", line 55, in inner
    response = get_response(request)
               ^^^^^^^^^^^^^^^^^^^^^
  File "/home/lighvzkx/virtualenv/max_app/3.11/lib/python3.11/site-packages/django/utils/deprecation.py", line 134, in __call__
    response = response or self.get_response(request)
                           ^^^^^^^^^^^^^^^^^^^^^^^^^^
  File "/home/lighvzkx/virtualenv/max_app/3.11/lib/python3.11/site-packages/django/core/handlers/exception.py", line 57, in inner
    response = response_for_exception(request, exc)
               ^^^^^^^^^^^^^^^^^^^^^^^^^^^^^^^^^^^^
  File "/home/lighvzkx/virtualenv/max_app/3.11/lib/python3.11/site-packages/django/core/handlers/exception.py", line 140, in response_for_exception
    response = handle_uncaught_exception(
               ^^^^^^^^^^^^^^^^^^^^^^^^^^
  File "/home/lighvzkx/virtualenv/max_app/3.11/lib/python3.11/site-packages/django/core/handlers/exception.py", line 181, in handle_uncaught_exception
    return debug.technical_500_response(request, *exc_info)
           ^^^^^^^^^^^^^^^^^^^^^^^^^^^^^^^^^^^^^^^^^^^^^^^^
  File "/home/lighvzkx/virtualenv/max_app/3.11/lib/python3.11/site-packages/django/views/debug.py", line 67, in technical_500_response
    html = reporter.get_traceback_html()
           ^^^^^^^^^^^^^^^^^^^^^^^^^^^^^
  File "/home/lighvzkx/virtualenv/max_app/3.11/lib/python3.11/site-packages/django/views/debug.py", line 410, in get_traceback_html
    c = Context(self.get_traceback_data(), use_l10n=False)
                ^^^^^^^^^^^^^^^^^^^^^^^^^
  File "/home/lighvzkx/virtualenv/max_app/3.11/lib/python3.11/site-packages/django/views/debug.py", line 393, in get_traceback_data
    c["raising_view_name"] = get_caller(self.request)
                             ^^^^^^^^^^^^^^^^^^^^^^^^
  File "/home/lighvzkx/virtualenv/max_app/3.11/lib/python3.11/site-packages/django/views/debug.py", line 100, in get_caller
    resolver_match = resolve(request.path)
                     ^^^^^^^^^^^^^^^^^^^^^
  File "/home/lighvzkx/virtualenv/max_app/3.11/lib/python3.11/site-packages/django/urls/base.py", line 24, in resolve
    return get_resolver(urlconf).resolve(path)
           ^^^^^^^^^^^^^^^^^^^^^^^^^^^^^^^^^^^
  File "/home/lighvzkx/virtualenv/max_app/3.11/lib/python3.11/site-packages/django/urls/resolvers.py", line 665, in resolve
    sub_match = pattern.resolve(new_path)
                ^^^^^^^^^^^^^^^^^^^^^^^^^
  File "/home/lighvzkx/virtualenv/max_app/3.11/lib/python3.11/site-packages/django/urls/resolvers.py", line 663, in resolve
    for pattern in self.url_patterns:
                   ^^^^^^^^^^^^^^^^^
  File "/home/lighvzkx/virtualenv/max_app/3.11/lib/python3.11/site-packages/django/utils/functional.py", line 57, in __get__
    res = instance.__dict__[self.name] = self.func(instance)
                                         ^^^^^^^^^^^^^^^^^^^
  File "/home/lighvzkx/virtualenv/max_app/3.11/lib/python3.11/site-packages/django/urls/resolvers.py", line 725, in url_patterns
    raise ImproperlyConfigured(msg.format(name=self.urlconf_name)) from e
django.core.exceptions.ImproperlyConfigured: The included URLconf '<module 'business.urls' from '/home/lighvzkx/max_app/business/urls.py'>' does not appear to have any patterns in it. If you see the 'urlpatterns' variable with valid patterns in the file then the issue is probably caused by a circular import.

During handling of the above exception, another exception occurred:

Traceback (most recent call last):
  File "/home/lighvzkx/virtualenv/max_app/3.11/lib/python3.11/site-packages/django/urls/resolvers.py", line 717, in url_patterns
    iter(patterns)
TypeError: 'module' object is not iterable

The above exception was the direct cause of the following exception:

Traceback (most recent call last):
  File "/home/lighvzkx/virtualenv/max_app/3.11/lib/python3.11/site-packages/django/core/handlers/exception.py", line 55, in inner
    response = get_response(request)
               ^^^^^^^^^^^^^^^^^^^^^
  File "/home/lighvzkx/virtualenv/max_app/3.11/lib/python3.11/site-packages/django/utils/deprecation.py", line 134, in __call__
    response = response or self.get_response(request)
                           ^^^^^^^^^^^^^^^^^^^^^^^^^^
  File "/home/lighvzkx/virtualenv/max_app/3.11/lib/python3.11/site-packages/django/core/handlers/exception.py", line 57, in inner
    response = response_for_exception(request, exc)
               ^^^^^^^^^^^^^^^^^^^^^^^^^^^^^^^^^^^^
  File "/home/lighvzkx/virtualenv/max_app/3.11/lib/python3.11/site-packages/django/core/handlers/exception.py", line 140, in response_for_exception
    response = handle_uncaught_exception(
               ^^^^^^^^^^^^^^^^^^^^^^^^^^
  File "/home/lighvzkx/virtualenv/max_app/3.11/lib/python3.11/site-packages/django/core/handlers/exception.py", line 181, in handle_uncaught_exception
    return debug.technical_500_response(request, *exc_info)
           ^^^^^^^^^^^^^^^^^^^^^^^^^^^^^^^^^^^^^^^^^^^^^^^^
  File "/home/lighvzkx/virtualenv/max_app/3.11/lib/python3.11/site-packages/django/views/debug.py", line 67, in technical_500_response
    html = reporter.get_traceback_html()
           ^^^^^^^^^^^^^^^^^^^^^^^^^^^^^
  File "/home/lighvzkx/virtualenv/max_app/3.11/lib/python3.11/site-packages/django/views/debug.py", line 410, in get_traceback_html
    c = Context(self.get_traceback_data(), use_l10n=False)
                ^^^^^^^^^^^^^^^^^^^^^^^^^
  File "/home/lighvzkx/virtualenv/max_app/3.11/lib/python3.11/site-packages/django/views/debug.py", line 393, in get_traceback_data
    c["raising_view_name"] = get_caller(self.request)
                             ^^^^^^^^^^^^^^^^^^^^^^^^
  File "/home/lighvzkx/virtualenv/max_app/3.11/lib/python3.11/site-packages/django/views/debug.py", line 100, in get_caller
    resolver_match = resolve(request.path)
                     ^^^^^^^^^^^^^^^^^^^^^
  File "/home/lighvzkx/virtualenv/max_app/3.11/lib/python3.11/site-packages/django/urls/base.py", line 24, in resolve
    return get_resolver(urlconf).resolve(path)
           ^^^^^^^^^^^^^^^^^^^^^^^^^^^^^^^^^^^
  File "/home/lighvzkx/virtualenv/max_app/3.11/lib/python3.11/site-packages/django/urls/resolvers.py", line 665, in resolve
    sub_match = pattern.resolve(new_path)
                ^^^^^^^^^^^^^^^^^^^^^^^^^
  File "/home/lighvzkx/virtualenv/max_app/3.11/lib/python3.11/site-packages/django/urls/resolvers.py", line 663, in resolve
    for pattern in self.url_patterns:
                   ^^^^^^^^^^^^^^^^^
  File "/home/lighvzkx/virtualenv/max_app/3.11/lib/python3.11/site-packages/django/utils/functional.py", line 57, in __get__
    res = instance.__dict__[self.name] = self.func(instance)
                                         ^^^^^^^^^^^^^^^^^^^
  File "/home/lighvzkx/virtualenv/max_app/3.11/lib/python3.11/site-packages/django/urls/resolvers.py", line 725, in url_patterns
    raise ImproperlyConfigured(msg.format(name=self.urlconf_name)) from e
django.core.exceptions.ImproperlyConfigured: The included URLconf '<module 'business.urls' from '/home/lighvzkx/max_app/business/urls.py'>' does not appear to have any patterns in it. If you see the 'urlpatterns' variable with valid patterns in the file then the issue is probably caused by a circular import.

During handling of the above exception, another exception occurred:

Traceback (most recent call last):
  File "/home/lighvzkx/virtualenv/max_app/3.11/lib/python3.11/site-packages/django/urls/resolvers.py", line 717, in url_patterns
    iter(patterns)
TypeError: 'module' object is not iterable

The above exception was the direct cause of the following exception:

Traceback (most recent call last):
  File "/home/lighvzkx/virtualenv/max_app/3.11/lib/python3.11/site-packages/django/core/handlers/exception.py", line 55, in inner
    response = get_response(request)
               ^^^^^^^^^^^^^^^^^^^^^
  File "/home/lighvzkx/virtualenv/max_app/3.11/lib/python3.11/site-packages/django/utils/deprecation.py", line 134, in __call__
    response = response or self.get_response(request)
                           ^^^^^^^^^^^^^^^^^^^^^^^^^^
  File "/home/lighvzkx/virtualenv/max_app/3.11/lib/python3.11/site-packages/django/core/handlers/exception.py", line 57, in inner
    response = response_for_exception(request, exc)
               ^^^^^^^^^^^^^^^^^^^^^^^^^^^^^^^^^^^^
  File "/home/lighvzkx/virtualenv/max_app/3.11/lib/python3.11/site-packages/django/core/handlers/exception.py", line 140, in response_for_exception
    response = handle_uncaught_exception(
               ^^^^^^^^^^^^^^^^^^^^^^^^^^
  File "/home/lighvzkx/virtualenv/max_app/3.11/lib/python3.11/site-packages/django/core/handlers/exception.py", line 181, in handle_uncaught_exception
    return debug.technical_500_response(request, *exc_info)
           ^^^^^^^^^^^^^^^^^^^^^^^^^^^^^^^^^^^^^^^^^^^^^^^^
  File "/home/lighvzkx/virtualenv/max_app/3.11/lib/python3.11/site-packages/django/views/debug.py", line 67, in technical_500_response
    html = reporter.get_traceback_html()
           ^^^^^^^^^^^^^^^^^^^^^^^^^^^^^
  File "/home/lighvzkx/virtualenv/max_app/3.11/lib/python3.11/site-packages/django/views/debug.py", line 410, in get_traceback_html
    c = Context(self.get_traceback_data(), use_l10n=False)
                ^^^^^^^^^^^^^^^^^^^^^^^^^
  File "/home/lighvzkx/virtualenv/max_app/3.11/lib/python3.11/site-packages/django/views/debug.py", line 393, in get_traceback_data
    c["raising_view_name"] = get_caller(self.request)
                             ^^^^^^^^^^^^^^^^^^^^^^^^
  File "/home/lighvzkx/virtualenv/max_app/3.11/lib/python3.11/site-packages/django/views/debug.py", line 100, in get_caller
    resolver_match = resolve(request.path)
                     ^^^^^^^^^^^^^^^^^^^^^
  File "/home/lighvzkx/virtualenv/max_app/3.11/lib/python3.11/site-packages/django/urls/base.py", line 24, in resolve
    return get_resolver(urlconf).resolve(path)
           ^^^^^^^^^^^^^^^^^^^^^^^^^^^^^^^^^^^
  File "/home/lighvzkx/virtualenv/max_app/3.11/lib/python3.11/site-packages/django/urls/resolvers.py", line 665, in resolve
    sub_match = pattern.resolve(new_path)
                ^^^^^^^^^^^^^^^^^^^^^^^^^
  File "/home/lighvzkx/virtualenv/max_app/3.11/lib/python3.11/site-packages/django/urls/resolvers.py", line 663, in resolve
    for pattern in self.url_patterns:
                   ^^^^^^^^^^^^^^^^^
  File "/home/lighvzkx/virtualenv/max_app/3.11/lib/python3.11/site-packages/django/utils/functional.py", line 57, in __get__
    res = instance.__dict__[self.name] = self.func(instance)
                                         ^^^^^^^^^^^^^^^^^^^
  File "/home/lighvzkx/virtualenv/max_app/3.11/lib/python3.11/site-packages/django/urls/resolvers.py", line 725, in url_patterns
    raise ImproperlyConfigured(msg.format(name=self.urlconf_name)) from e
django.core.exceptions.ImproperlyConfigured: The included URLconf '<module 'business.urls' from '/home/lighvzkx/max_app/business/urls.py'>' does not appear to have any patterns in it. If you see the 'urlpatterns' variable with valid patterns in the file then the issue is probably caused by a circular import.

During handling of the above exception, another exception occurred:

Traceback (most recent call last):
  File "/home/lighvzkx/virtualenv/max_app/3.11/lib/python3.11/site-packages/django/urls/resolvers.py", line 717, in url_patterns
    iter(patterns)
TypeError: 'module' object is not iterable

The above exception was the direct cause of the following exception:

Traceback (most recent call last):
  File "/home/lighvzkx/virtualenv/max_app/3.11/lib/python3.11/site-packages/django/core/handlers/exception.py", line 55, in inner
    response = get_response(request)
               ^^^^^^^^^^^^^^^^^^^^^
  File "/home/lighvzkx/virtualenv/max_app/3.11/lib/python3.11/site-packages/django/utils/deprecation.py", line 134, in __call__
    response = response or self.get_response(request)
                           ^^^^^^^^^^^^^^^^^^^^^^^^^^
  File "/home/lighvzkx/virtualenv/max_app/3.11/lib/python3.11/site-packages/django/core/handlers/exception.py", line 57, in inner
    response = response_for_exception(request, exc)
               ^^^^^^^^^^^^^^^^^^^^^^^^^^^^^^^^^^^^
  File "/home/lighvzkx/virtualenv/max_app/3.11/lib/python3.11/site-packages/django/core/handlers/exception.py", line 140, in response_for_exception
    response = handle_uncaught_exception(
               ^^^^^^^^^^^^^^^^^^^^^^^^^^
  File "/home/lighvzkx/virtualenv/max_app/3.11/lib/python3.11/site-packages/django/core/handlers/exception.py", line 181, in handle_uncaught_exception
    return debug.technical_500_response(request, *exc_info)
           ^^^^^^^^^^^^^^^^^^^^^^^^^^^^^^^^^^^^^^^^^^^^^^^^
  File "/home/lighvzkx/virtualenv/max_app/3.11/lib/python3.11/site-packages/django/views/debug.py", line 67, in technical_500_response
    html = reporter.get_traceback_html()
           ^^^^^^^^^^^^^^^^^^^^^^^^^^^^^
  File "/home/lighvzkx/virtualenv/max_app/3.11/lib/python3.11/site-packages/django/views/debug.py", line 410, in get_traceback_html
    c = Context(self.get_traceback_data(), use_l10n=False)
                ^^^^^^^^^^^^^^^^^^^^^^^^^
  File "/home/lighvzkx/virtualenv/max_app/3.11/lib/python3.11/site-packages/django/views/debug.py", line 393, in get_traceback_data
    c["raising_view_name"] = get_caller(self.request)
                             ^^^^^^^^^^^^^^^^^^^^^^^^
  File "/home/lighvzkx/virtualenv/max_app/3.11/lib/python3.11/site-packages/django/views/debug.py", line 100, in get_caller
    resolver_match = resolve(request.path)
                     ^^^^^^^^^^^^^^^^^^^^^
  File "/home/lighvzkx/virtualenv/max_app/3.11/lib/python3.11/site-packages/django/urls/base.py", line 24, in resolve
    return get_resolver(urlconf).resolve(path)
           ^^^^^^^^^^^^^^^^^^^^^^^^^^^^^^^^^^^
  File "/home/lighvzkx/virtualenv/max_app/3.11/lib/python3.11/site-packages/django/urls/resolvers.py", line 665, in resolve
    sub_match = pattern.resolve(new_path)
                ^^^^^^^^^^^^^^^^^^^^^^^^^
  File "/home/lighvzkx/virtualenv/max_app/3.11/lib/python3.11/site-packages/django/urls/resolvers.py", line 663, in resolve
    for pattern in self.url_patterns:
                   ^^^^^^^^^^^^^^^^^
  File "/home/lighvzkx/virtualenv/max_app/3.11/lib/python3.11/site-packages/django/utils/functional.py", line 57, in __get__
    res = instance.__dict__[self.name] = self.func(instance)
                                         ^^^^^^^^^^^^^^^^^^^
  File "/home/lighvzkx/virtualenv/max_app/3.11/lib/python3.11/site-packages/django/urls/resolvers.py", line 725, in url_patterns
    raise ImproperlyConfigured(msg.format(name=self.urlconf_name)) from e
django.core.exceptions.ImproperlyConfigured: The included URLconf '<module 'business.urls' from '/home/lighvzkx/max_app/business/urls.py'>' does not appear to have any patterns in it. If you see the 'urlpatterns' variable with valid patterns in the file then the issue is probably caused by a circular import.

During handling of the above exception, another exception occurred:

Traceback (most recent call last):
  File "/home/lighvzkx/virtualenv/max_app/3.11/lib/python3.11/site-packages/django/urls/resolvers.py", line 717, in url_patterns
    iter(patterns)
TypeError: 'module' object is not iterable

The above exception was the direct cause of the following exception:

Traceback (most recent call last):
  File "/home/lighvzkx/virtualenv/max_app/3.11/lib/python3.11/site-packages/django/core/handlers/exception.py", line 55, in inner
    response = get_response(request)
               ^^^^^^^^^^^^^^^^^^^^^
  File "/home/lighvzkx/virtualenv/max_app/3.11/lib/python3.11/site-packages/django/utils/deprecation.py", line 134, in __call__
    response = response or self.get_response(request)
                           ^^^^^^^^^^^^^^^^^^^^^^^^^^
  File "/home/lighvzkx/virtualenv/max_app/3.11/lib/python3.11/site-packages/django/core/handlers/exception.py", line 57, in inner
    response = response_for_exception(request, exc)
               ^^^^^^^^^^^^^^^^^^^^^^^^^^^^^^^^^^^^
  File "/home/lighvzkx/virtualenv/max_app/3.11/lib/python3.11/site-packages/django/core/handlers/exception.py", line 140, in response_for_exception
    response = handle_uncaught_exception(
               ^^^^^^^^^^^^^^^^^^^^^^^^^^
  File "/home/lighvzkx/virtualenv/max_app/3.11/lib/python3.11/site-packages/django/core/handlers/exception.py", line 181, in handle_uncaught_exception
    return debug.technical_500_response(request, *exc_info)
           ^^^^^^^^^^^^^^^^^^^^^^^^^^^^^^^^^^^^^^^^^^^^^^^^
  File "/home/lighvzkx/virtualenv/max_app/3.11/lib/python3.11/site-packages/django/views/debug.py", line 67, in technical_500_response
    html = reporter.get_traceback_html()
           ^^^^^^^^^^^^^^^^^^^^^^^^^^^^^
  File "/home/lighvzkx/virtualenv/max_app/3.11/lib/python3.11/site-packages/django/views/debug.py", line 410, in get_traceback_html
    c = Context(self.get_traceback_data(), use_l10n=False)
                ^^^^^^^^^^^^^^^^^^^^^^^^^
  File "/home/lighvzkx/virtualenv/max_app/3.11/lib/python3.11/site-packages/django/views/debug.py", line 393, in get_traceback_data
    c["raising_view_name"] = get_caller(self.request)
                             ^^^^^^^^^^^^^^^^^^^^^^^^
  File "/home/lighvzkx/virtualenv/max_app/3.11/lib/python3.11/site-packages/django/views/debug.py", line 100, in get_caller
    resolver_match = resolve(request.path)
                     ^^^^^^^^^^^^^^^^^^^^^
  File "/home/lighvzkx/virtualenv/max_app/3.11/lib/python3.11/site-packages/django/urls/base.py", line 24, in resolve
    return get_resolver(urlconf).resolve(path)
           ^^^^^^^^^^^^^^^^^^^^^^^^^^^^^^^^^^^
  File "/home/lighvzkx/virtualenv/max_app/3.11/lib/python3.11/site-packages/django/urls/resolvers.py", line 665, in resolve
    sub_match = pattern.resolve(new_path)
                ^^^^^^^^^^^^^^^^^^^^^^^^^
  File "/home/lighvzkx/virtualenv/max_app/3.11/lib/python3.11/site-packages/django/urls/resolvers.py", line 663, in resolve
    for pattern in self.url_patterns:
                   ^^^^^^^^^^^^^^^^^
  File "/home/lighvzkx/virtualenv/max_app/3.11/lib/python3.11/site-packages/django/utils/functional.py", line 57, in __get__
    res = instance.__dict__[self.name] = self.func(instance)
                                         ^^^^^^^^^^^^^^^^^^^
  File "/home/lighvzkx/virtualenv/max_app/3.11/lib/python3.11/site-packages/django/urls/resolvers.py", line 725, in url_patterns
    raise ImproperlyConfigured(msg.format(name=self.urlconf_name)) from e
django.core.exceptions.ImproperlyConfigured: The included URLconf '<module 'business.urls' from '/home/lighvzkx/max_app/business/urls.py'>' does not appear to have any patterns in it. If you see the 'urlpatterns' variable with valid patterns in the file then the issue is probably caused by a circular import.

During handling of the above exception, another exception occurred:

Traceback (most recent call last):
  File "/home/lighvzkx/virtualenv/max_app/3.11/lib/python3.11/site-packages/django/urls/resolvers.py", line 717, in url_patterns
    iter(patterns)
TypeError: 'module' object is not iterable

The above exception was the direct cause of the following exception:

Traceback (most recent call last):
  File "/home/lighvzkx/virtualenv/max_app/3.11/lib/python3.11/site-packages/django/core/handlers/wsgi.py", line 124, in __call__
    response = self.get_response(request)
               ^^^^^^^^^^^^^^^^^^^^^^^^^^
  File "/home/lighvzkx/virtualenv/max_app/3.11/lib/python3.11/site-packages/django/core/handlers/base.py", line 140, in get_response
    response = self._middleware_chain(request)
               ^^^^^^^^^^^^^^^^^^^^^^^^^^^^^^^
  File "/home/lighvzkx/virtualenv/max_app/3.11/lib/python3.11/site-packages/django/core/handlers/exception.py", line 57, in inner
    response = response_for_exception(request, exc)
               ^^^^^^^^^^^^^^^^^^^^^^^^^^^^^^^^^^^^
  File "/home/lighvzkx/virtualenv/max_app/3.11/lib/python3.11/site-packages/django/core/handlers/exception.py", line 140, in response_for_exception
    response = handle_uncaught_exception(
               ^^^^^^^^^^^^^^^^^^^^^^^^^^
  File "/home/lighvzkx/virtualenv/max_app/3.11/lib/python3.11/site-packages/django/core/handlers/exception.py", line 181, in handle_uncaught_exception
    return debug.technical_500_response(request, *exc_info)
           ^^^^^^^^^^^^^^^^^^^^^^^^^^^^^^^^^^^^^^^^^^^^^^^^
  File "/home/lighvzkx/virtualenv/max_app/3.11/lib/python3.11/site-packages/django/views/debug.py", line 67, in technical_500_response
    html = reporter.get_traceback_html()
           ^^^^^^^^^^^^^^^^^^^^^^^^^^^^^
  File "/home/lighvzkx/virtualenv/max_app/3.11/lib/python3.11/site-packages/django/views/debug.py", line 410, in get_traceback_html
    c = Context(self.get_traceback_data(), use_l10n=False)
                ^^^^^^^^^^^^^^^^^^^^^^^^^
  File "/home/lighvzkx/virtualenv/max_app/3.11/lib/python3.11/site-packages/django/views/debug.py", line 393, in get_traceback_data
    c["raising_view_name"] = get_caller(self.request)
                             ^^^^^^^^^^^^^^^^^^^^^^^^
  File "/home/lighvzkx/virtualenv/max_app/3.11/lib/python3.11/site-packages/django/views/debug.py", line 100, in get_caller
    resolver_match = resolve(request.path)
                     ^^^^^^^^^^^^^^^^^^^^^
  File "/home/lighvzkx/virtualenv/max_app/3.11/lib/python3.11/site-packages/django/urls/base.py", line 24, in resolve
    return get_resolver(urlconf).resolve(path)
           ^^^^^^^^^^^^^^^^^^^^^^^^^^^^^^^^^^^
  File "/home/lighvzkx/virtualenv/max_app/3.11/lib/python3.11/site-packages/django/urls/resolvers.py", line 665, in resolve
    sub_match = pattern.resolve(new_path)
                ^^^^^^^^^^^^^^^^^^^^^^^^^
  File "/home/lighvzkx/virtualenv/max_app/3.11/lib/python3.11/site-packages/django/urls/resolvers.py", line 663, in resolve
    for pattern in self.url_patterns:
                   ^^^^^^^^^^^^^^^^^
  File "/home/lighvzkx/virtualenv/max_app/3.11/lib/python3.11/site-packages/django/utils/functional.py", line 57, in __get__
    res = instance.__dict__[self.name] = self.func(instance)
                                         ^^^^^^^^^^^^^^^^^^^
  File "/home/lighvzkx/virtualenv/max_app/3.11/lib/python3.11/site-packages/django/urls/resolvers.py", line 725, in url_patterns
    raise ImproperlyConfigured(msg.format(name=self.urlconf_name)) from e
django.core.exceptions.ImproperlyConfigured: The included URLconf '<module 'business.urls' from '/home/lighvzkx/max_app/business/urls.py'>' does not appear to have any patterns in it. If you see the 'urlpatterns' variable with valid patterns in the file then the issue is probably caused by a circular import.
[ERROR] [UID:13895][2358] wsgiAppHandler pApp->start_response() return NULL.
Traceback (most recent call last):
  File "/home/lighvzkx/virtualenv/max_app/3.11/lib/python3.11/site-packages/django/urls/resolvers.py", line 717, in url_patterns
    iter(patterns)
TypeError: 'module' object is not iterable

The above exception was the direct cause of the following exception:

Traceback (most recent call last):
  File "/home/lighvzkx/virtualenv/max_app/3.11/lib/python3.11/site-packages/django/core/handlers/exception.py", line 55, in inner
    response = get_response(request)
               ^^^^^^^^^^^^^^^^^^^^^
  File "/home/lighvzkx/virtualenv/max_app/3.11/lib/python3.11/site-packages/django/core/handlers/base.py", line 181, in _get_response
    callback, callback_args, callback_kwargs = self.resolve_request(request)
                                               ^^^^^^^^^^^^^^^^^^^^^^^^^^^^^
  File "/home/lighvzkx/virtualenv/max_app/3.11/lib/python3.11/site-packages/django/core/handlers/base.py", line 313, in resolve_request
    resolver_match = resolver.resolve(request.path_info)
                     ^^^^^^^^^^^^^^^^^^^^^^^^^^^^^^^^^^^
  File "/home/lighvzkx/virtualenv/max_app/3.11/lib/python3.11/site-packages/django/urls/resolvers.py", line 665, in resolve
    sub_match = pattern.resolve(new_path)
                ^^^^^^^^^^^^^^^^^^^^^^^^^
  File "/home/lighvzkx/virtualenv/max_app/3.11/lib/python3.11/site-packages/django/urls/resolvers.py", line 663, in resolve
    for pattern in self.url_patterns:
                   ^^^^^^^^^^^^^^^^^
  File "/home/lighvzkx/virtualenv/max_app/3.11/lib/python3.11/site-packages/django/utils/functional.py", line 57, in __get__
    res = instance.__dict__[self.name] = self.func(instance)
                                         ^^^^^^^^^^^^^^^^^^^
  File "/home/lighvzkx/virtualenv/max_app/3.11/lib/python3.11/site-packages/django/urls/resolvers.py", line 725, in url_patterns
    raise ImproperlyConfigured(msg.format(name=self.urlconf_name)) from e
django.core.exceptions.ImproperlyConfigured: The included URLconf '<module 'business.urls' from '/home/lighvzkx/max_app/business/urls.py'>' does not appear to have any patterns in it. If you see the 'urlpatterns' variable with valid patterns in the file then the issue is probably caused by a circular import.

During handling of the above exception, another exception occurred:

Traceback (most recent call last):
  File "/home/lighvzkx/virtualenv/max_app/3.11/lib/python3.11/site-packages/django/urls/resolvers.py", line 717, in url_patterns
    iter(patterns)
TypeError: 'module' object is not iterable

The above exception was the direct cause of the following exception:

Traceback (most recent call last):
  File "/home/lighvzkx/virtualenv/max_app/3.11/lib/python3.11/site-packages/django/core/handlers/exception.py", line 55, in inner
    response = get_response(request)
               ^^^^^^^^^^^^^^^^^^^^^
  File "/home/lighvzkx/virtualenv/max_app/3.11/lib/python3.11/site-packages/django/utils/deprecation.py", line 134, in __call__
    response = response or self.get_response(request)
                           ^^^^^^^^^^^^^^^^^^^^^^^^^^
  File "/home/lighvzkx/virtualenv/max_app/3.11/lib/python3.11/site-packages/django/core/handlers/exception.py", line 57, in inner
    response = response_for_exception(request, exc)
               ^^^^^^^^^^^^^^^^^^^^^^^^^^^^^^^^^^^^
  File "/home/lighvzkx/virtualenv/max_app/3.11/lib/python3.11/site-packages/django/core/handlers/exception.py", line 140, in response_for_exception
    response = handle_uncaught_exception(
               ^^^^^^^^^^^^^^^^^^^^^^^^^^
  File "/home/lighvzkx/virtualenv/max_app/3.11/lib/python3.11/site-packages/django/core/handlers/exception.py", line 181, in handle_uncaught_exception
    return debug.technical_500_response(request, *exc_info)
           ^^^^^^^^^^^^^^^^^^^^^^^^^^^^^^^^^^^^^^^^^^^^^^^^
  File "/home/lighvzkx/virtualenv/max_app/3.11/lib/python3.11/site-packages/django/views/debug.py", line 67, in technical_500_response
    html = reporter.get_traceback_html()
           ^^^^^^^^^^^^^^^^^^^^^^^^^^^^^
  File "/home/lighvzkx/virtualenv/max_app/3.11/lib/python3.11/site-packages/django/views/debug.py", line 410, in get_traceback_html
    c = Context(self.get_traceback_data(), use_l10n=False)
                ^^^^^^^^^^^^^^^^^^^^^^^^^
  File "/home/lighvzkx/virtualenv/max_app/3.11/lib/python3.11/site-packages/django/views/debug.py", line 393, in get_traceback_data
    c["raising_view_name"] = get_caller(self.request)
                             ^^^^^^^^^^^^^^^^^^^^^^^^
  File "/home/lighvzkx/virtualenv/max_app/3.11/lib/python3.11/site-packages/django/views/debug.py", line 100, in get_caller
    resolver_match = resolve(request.path)
                     ^^^^^^^^^^^^^^^^^^^^^
  File "/home/lighvzkx/virtualenv/max_app/3.11/lib/python3.11/site-packages/django/urls/base.py", line 24, in resolve
    return get_resolver(urlconf).resolve(path)
           ^^^^^^^^^^^^^^^^^^^^^^^^^^^^^^^^^^^
  File "/home/lighvzkx/virtualenv/max_app/3.11/lib/python3.11/site-packages/django/urls/resolvers.py", line 665, in resolve
    sub_match = pattern.resolve(new_path)
                ^^^^^^^^^^^^^^^^^^^^^^^^^
  File "/home/lighvzkx/virtualenv/max_app/3.11/lib/python3.11/site-packages/django/urls/resolvers.py", line 663, in resolve
    for pattern in self.url_patterns:
                   ^^^^^^^^^^^^^^^^^
  File "/home/lighvzkx/virtualenv/max_app/3.11/lib/python3.11/site-packages/django/utils/functional.py", line 57, in __get__
    res = instance.__dict__[self.name] = self.func(instance)
                                         ^^^^^^^^^^^^^^^^^^^
  File "/home/lighvzkx/virtualenv/max_app/3.11/lib/python3.11/site-packages/django/urls/resolvers.py", line 725, in url_patterns
    raise ImproperlyConfigured(msg.format(name=self.urlconf_name)) from e
django.core.exceptions.ImproperlyConfigured: The included URLconf '<module 'business.urls' from '/home/lighvzkx/max_app/business/urls.py'>' does not appear to have any patterns in it. If you see the 'urlpatterns' variable with valid patterns in the file then the issue is probably caused by a circular import.

During handling of the above exception, another exception occurred:

Traceback (most recent call last):
  File "/home/lighvzkx/virtualenv/max_app/3.11/lib/python3.11/site-packages/django/urls/resolvers.py", line 717, in url_patterns
    iter(patterns)
TypeError: 'module' object is not iterable

The above exception was the direct cause of the following exception:

Traceback (most recent call last):
  File "/home/lighvzkx/virtualenv/max_app/3.11/lib/python3.11/site-packages/django/core/handlers/exception.py", line 55, in inner
    response = get_response(request)
               ^^^^^^^^^^^^^^^^^^^^^
  File "/home/lighvzkx/virtualenv/max_app/3.11/lib/python3.11/site-packages/django/utils/deprecation.py", line 134, in __call__
    response = response or self.get_response(request)
                           ^^^^^^^^^^^^^^^^^^^^^^^^^^
  File "/home/lighvzkx/virtualenv/max_app/3.11/lib/python3.11/site-packages/django/core/handlers/exception.py", line 57, in inner
    response = response_for_exception(request, exc)
               ^^^^^^^^^^^^^^^^^^^^^^^^^^^^^^^^^^^^
  File "/home/lighvzkx/virtualenv/max_app/3.11/lib/python3.11/site-packages/django/core/handlers/exception.py", line 140, in response_for_exception
    response = handle_uncaught_exception(
               ^^^^^^^^^^^^^^^^^^^^^^^^^^
  File "/home/lighvzkx/virtualenv/max_app/3.11/lib/python3.11/site-packages/django/core/handlers/exception.py", line 181, in handle_uncaught_exception
    return debug.technical_500_response(request, *exc_info)
           ^^^^^^^^^^^^^^^^^^^^^^^^^^^^^^^^^^^^^^^^^^^^^^^^
  File "/home/lighvzkx/virtualenv/max_app/3.11/lib/python3.11/site-packages/django/views/debug.py", line 67, in technical_500_response
    html = reporter.get_traceback_html()
           ^^^^^^^^^^^^^^^^^^^^^^^^^^^^^
  File "/home/lighvzkx/virtualenv/max_app/3.11/lib/python3.11/site-packages/django/views/debug.py", line 410, in get_traceback_html
    c = Context(self.get_traceback_data(), use_l10n=False)
                ^^^^^^^^^^^^^^^^^^^^^^^^^
  File "/home/lighvzkx/virtualenv/max_app/3.11/lib/python3.11/site-packages/django/views/debug.py", line 393, in get_traceback_data
    c["raising_view_name"] = get_caller(self.request)
                             ^^^^^^^^^^^^^^^^^^^^^^^^
  File "/home/lighvzkx/virtualenv/max_app/3.11/lib/python3.11/site-packages/django/views/debug.py", line 100, in get_caller
    resolver_match = resolve(request.path)
                     ^^^^^^^^^^^^^^^^^^^^^
  File "/home/lighvzkx/virtualenv/max_app/3.11/lib/python3.11/site-packages/django/urls/base.py", line 24, in resolve
    return get_resolver(urlconf).resolve(path)
           ^^^^^^^^^^^^^^^^^^^^^^^^^^^^^^^^^^^
  File "/home/lighvzkx/virtualenv/max_app/3.11/lib/python3.11/site-packages/django/urls/resolvers.py", line 665, in resolve
    sub_match = pattern.resolve(new_path)
                ^^^^^^^^^^^^^^^^^^^^^^^^^
  File "/home/lighvzkx/virtualenv/max_app/3.11/lib/python3.11/site-packages/django/urls/resolvers.py", line 663, in resolve
    for pattern in self.url_patterns:
                   ^^^^^^^^^^^^^^^^^
  File "/home/lighvzkx/virtualenv/max_app/3.11/lib/python3.11/site-packages/django/utils/functional.py", line 57, in __get__
    res = instance.__dict__[self.name] = self.func(instance)
                                         ^^^^^^^^^^^^^^^^^^^
  File "/home/lighvzkx/virtualenv/max_app/3.11/lib/python3.11/site-packages/django/urls/resolvers.py", line 725, in url_patterns
    raise ImproperlyConfigured(msg.format(name=self.urlconf_name)) from e
django.core.exceptions.ImproperlyConfigured: The included URLconf '<module 'business.urls' from '/home/lighvzkx/max_app/business/urls.py'>' does not appear to have any patterns in it. If you see the 'urlpatterns' variable with valid patterns in the file then the issue is probably caused by a circular import.

During handling of the above exception, another exception occurred:

Traceback (most recent call last):
  File "/home/lighvzkx/virtualenv/max_app/3.11/lib/python3.11/site-packages/django/urls/resolvers.py", line 717, in url_patterns
    iter(patterns)
TypeError: 'module' object is not iterable

The above exception was the direct cause of the following exception:

Traceback (most recent call last):
  File "/home/lighvzkx/virtualenv/max_app/3.11/lib/python3.11/site-packages/django/core/handlers/exception.py", line 55, in inner
    response = get_response(request)
               ^^^^^^^^^^^^^^^^^^^^^
  File "/home/lighvzkx/virtualenv/max_app/3.11/lib/python3.11/site-packages/django/utils/deprecation.py", line 134, in __call__
    response = response or self.get_response(request)
                           ^^^^^^^^^^^^^^^^^^^^^^^^^^
  File "/home/lighvzkx/virtualenv/max_app/3.11/lib/python3.11/site-packages/django/core/handlers/exception.py", line 57, in inner
    response = response_for_exception(request, exc)
               ^^^^^^^^^^^^^^^^^^^^^^^^^^^^^^^^^^^^
  File "/home/lighvzkx/virtualenv/max_app/3.11/lib/python3.11/site-packages/django/core/handlers/exception.py", line 140, in response_for_exception
    response = handle_uncaught_exception(
               ^^^^^^^^^^^^^^^^^^^^^^^^^^
  File "/home/lighvzkx/virtualenv/max_app/3.11/lib/python3.11/site-packages/django/core/handlers/exception.py", line 181, in handle_uncaught_exception
    return debug.technical_500_response(request, *exc_info)
           ^^^^^^^^^^^^^^^^^^^^^^^^^^^^^^^^^^^^^^^^^^^^^^^^
  File "/home/lighvzkx/virtualenv/max_app/3.11/lib/python3.11/site-packages/django/views/debug.py", line 67, in technical_500_response
    html = reporter.get_traceback_html()
           ^^^^^^^^^^^^^^^^^^^^^^^^^^^^^
  File "/home/lighvzkx/virtualenv/max_app/3.11/lib/python3.11/site-packages/django/views/debug.py", line 410, in get_traceback_html
    c = Context(self.get_traceback_data(), use_l10n=False)
                ^^^^^^^^^^^^^^^^^^^^^^^^^
  File "/home/lighvzkx/virtualenv/max_app/3.11/lib/python3.11/site-packages/django/views/debug.py", line 393, in get_traceback_data
    c["raising_view_name"] = get_caller(self.request)
                             ^^^^^^^^^^^^^^^^^^^^^^^^
  File "/home/lighvzkx/virtualenv/max_app/3.11/lib/python3.11/site-packages/django/views/debug.py", line 100, in get_caller
    resolver_match = resolve(request.path)
                     ^^^^^^^^^^^^^^^^^^^^^
  File "/home/lighvzkx/virtualenv/max_app/3.11/lib/python3.11/site-packages/django/urls/base.py", line 24, in resolve
    return get_resolver(urlconf).resolve(path)
           ^^^^^^^^^^^^^^^^^^^^^^^^^^^^^^^^^^^
  File "/home/lighvzkx/virtualenv/max_app/3.11/lib/python3.11/site-packages/django/urls/resolvers.py", line 665, in resolve
    sub_match = pattern.resolve(new_path)
                ^^^^^^^^^^^^^^^^^^^^^^^^^
  File "/home/lighvzkx/virtualenv/max_app/3.11/lib/python3.11/site-packages/django/urls/resolvers.py", line 663, in resolve
    for pattern in self.url_patterns:
                   ^^^^^^^^^^^^^^^^^
  File "/home/lighvzkx/virtualenv/max_app/3.11/lib/python3.11/site-packages/django/utils/functional.py", line 57, in __get__
    res = instance.__dict__[self.name] = self.func(instance)
                                         ^^^^^^^^^^^^^^^^^^^
  File "/home/lighvzkx/virtualenv/max_app/3.11/lib/python3.11/site-packages/django/urls/resolvers.py", line 725, in url_patterns
    raise ImproperlyConfigured(msg.format(name=self.urlconf_name)) from e
django.core.exceptions.ImproperlyConfigured: The included URLconf '<module 'business.urls' from '/home/lighvzkx/max_app/business/urls.py'>' does not appear to have any patterns in it. If you see the 'urlpatterns' variable with valid patterns in the file then the issue is probably caused by a circular import.

During handling of the above exception, another exception occurred:

Traceback (most recent call last):
  File "/home/lighvzkx/virtualenv/max_app/3.11/lib/python3.11/site-packages/django/urls/resolvers.py", line 717, in url_patterns
    iter(patterns)
TypeError: 'module' object is not iterable

The above exception was the direct cause of the following exception:

Traceback (most recent call last):
  File "/home/lighvzkx/virtualenv/max_app/3.11/lib/python3.11/site-packages/django/core/handlers/exception.py", line 55, in inner
    response = get_response(request)
               ^^^^^^^^^^^^^^^^^^^^^
  File "/home/lighvzkx/virtualenv/max_app/3.11/lib/python3.11/site-packages/django/utils/deprecation.py", line 134, in __call__
    response = response or self.get_response(request)
                           ^^^^^^^^^^^^^^^^^^^^^^^^^^
  File "/home/lighvzkx/virtualenv/max_app/3.11/lib/python3.11/site-packages/django/core/handlers/exception.py", line 57, in inner
    response = response_for_exception(request, exc)
               ^^^^^^^^^^^^^^^^^^^^^^^^^^^^^^^^^^^^
  File "/home/lighvzkx/virtualenv/max_app/3.11/lib/python3.11/site-packages/django/core/handlers/exception.py", line 140, in response_for_exception
    response = handle_uncaught_exception(
               ^^^^^^^^^^^^^^^^^^^^^^^^^^
  File "/home/lighvzkx/virtualenv/max_app/3.11/lib/python3.11/site-packages/django/core/handlers/exception.py", line 181, in handle_uncaught_exception
    return debug.technical_500_response(request, *exc_info)
           ^^^^^^^^^^^^^^^^^^^^^^^^^^^^^^^^^^^^^^^^^^^^^^^^
  File "/home/lighvzkx/virtualenv/max_app/3.11/lib/python3.11/site-packages/django/views/debug.py", line 67, in technical_500_response
    html = reporter.get_traceback_html()
           ^^^^^^^^^^^^^^^^^^^^^^^^^^^^^
  File "/home/lighvzkx/virtualenv/max_app/3.11/lib/python3.11/site-packages/django/views/debug.py", line 410, in get_traceback_html
    c = Context(self.get_traceback_data(), use_l10n=False)
                ^^^^^^^^^^^^^^^^^^^^^^^^^
  File "/home/lighvzkx/virtualenv/max_app/3.11/lib/python3.11/site-packages/django/views/debug.py", line 393, in get_traceback_data
    c["raising_view_name"] = get_caller(self.request)
                             ^^^^^^^^^^^^^^^^^^^^^^^^
  File "/home/lighvzkx/virtualenv/max_app/3.11/lib/python3.11/site-packages/django/views/debug.py", line 100, in get_caller
    resolver_match = resolve(request.path)
                     ^^^^^^^^^^^^^^^^^^^^^
  File "/home/lighvzkx/virtualenv/max_app/3.11/lib/python3.11/site-packages/django/urls/base.py", line 24, in resolve
    return get_resolver(urlconf).resolve(path)
           ^^^^^^^^^^^^^^^^^^^^^^^^^^^^^^^^^^^
  File "/home/lighvzkx/virtualenv/max_app/3.11/lib/python3.11/site-packages/django/urls/resolvers.py", line 665, in resolve
    sub_match = pattern.resolve(new_path)
                ^^^^^^^^^^^^^^^^^^^^^^^^^
  File "/home/lighvzkx/virtualenv/max_app/3.11/lib/python3.11/site-packages/django/urls/resolvers.py", line 663, in resolve
    for pattern in self.url_patterns:
                   ^^^^^^^^^^^^^^^^^
  File "/home/lighvzkx/virtualenv/max_app/3.11/lib/python3.11/site-packages/django/utils/functional.py", line 57, in __get__
    res = instance.__dict__[self.name] = self.func(instance)
                                         ^^^^^^^^^^^^^^^^^^^
  File "/home/lighvzkx/virtualenv/max_app/3.11/lib/python3.11/site-packages/django/urls/resolvers.py", line 725, in url_patterns
    raise ImproperlyConfigured(msg.format(name=self.urlconf_name)) from e
django.core.exceptions.ImproperlyConfigured: The included URLconf '<module 'business.urls' from '/home/lighvzkx/max_app/business/urls.py'>' does not appear to have any patterns in it. If you see the 'urlpatterns' variable with valid patterns in the file then the issue is probably caused by a circular import.

During handling of the above exception, another exception occurred:

Traceback (most recent call last):
  File "/home/lighvzkx/virtualenv/max_app/3.11/lib/python3.11/site-packages/django/urls/resolvers.py", line 717, in url_patterns
    iter(patterns)
TypeError: 'module' object is not iterable

The above exception was the direct cause of the following exception:

Traceback (most recent call last):
  File "/home/lighvzkx/virtualenv/max_app/3.11/lib/python3.11/site-packages/django/core/handlers/exception.py", line 55, in inner
    response = get_response(request)
               ^^^^^^^^^^^^^^^^^^^^^
  File "/home/lighvzkx/virtualenv/max_app/3.11/lib/python3.11/site-packages/django/utils/deprecation.py", line 134, in __call__
    response = response or self.get_response(request)
                           ^^^^^^^^^^^^^^^^^^^^^^^^^^
  File "/home/lighvzkx/virtualenv/max_app/3.11/lib/python3.11/site-packages/django/core/handlers/exception.py", line 57, in inner
    response = response_for_exception(request, exc)
               ^^^^^^^^^^^^^^^^^^^^^^^^^^^^^^^^^^^^
  File "/home/lighvzkx/virtualenv/max_app/3.11/lib/python3.11/site-packages/django/core/handlers/exception.py", line 140, in response_for_exception
    response = handle_uncaught_exception(
               ^^^^^^^^^^^^^^^^^^^^^^^^^^
  File "/home/lighvzkx/virtualenv/max_app/3.11/lib/python3.11/site-packages/django/core/handlers/exception.py", line 181, in handle_uncaught_exception
    return debug.technical_500_response(request, *exc_info)
           ^^^^^^^^^^^^^^^^^^^^^^^^^^^^^^^^^^^^^^^^^^^^^^^^
  File "/home/lighvzkx/virtualenv/max_app/3.11/lib/python3.11/site-packages/django/views/debug.py", line 67, in technical_500_response
    html = reporter.get_traceback_html()
           ^^^^^^^^^^^^^^^^^^^^^^^^^^^^^
  File "/home/lighvzkx/virtualenv/max_app/3.11/lib/python3.11/site-packages/django/views/debug.py", line 410, in get_traceback_html
    c = Context(self.get_traceback_data(), use_l10n=False)
                ^^^^^^^^^^^^^^^^^^^^^^^^^
  File "/home/lighvzkx/virtualenv/max_app/3.11/lib/python3.11/site-packages/django/views/debug.py", line 393, in get_traceback_data
    c["raising_view_name"] = get_caller(self.request)
                             ^^^^^^^^^^^^^^^^^^^^^^^^
  File "/home/lighvzkx/virtualenv/max_app/3.11/lib/python3.11/site-packages/django/views/debug.py", line 100, in get_caller
    resolver_match = resolve(request.path)
                     ^^^^^^^^^^^^^^^^^^^^^
  File "/home/lighvzkx/virtualenv/max_app/3.11/lib/python3.11/site-packages/django/urls/base.py", line 24, in resolve
    return get_resolver(urlconf).resolve(path)
           ^^^^^^^^^^^^^^^^^^^^^^^^^^^^^^^^^^^
  File "/home/lighvzkx/virtualenv/max_app/3.11/lib/python3.11/site-packages/django/urls/resolvers.py", line 665, in resolve
    sub_match = pattern.resolve(new_path)
                ^^^^^^^^^^^^^^^^^^^^^^^^^
  File "/home/lighvzkx/virtualenv/max_app/3.11/lib/python3.11/site-packages/django/urls/resolvers.py", line 663, in resolve
    for pattern in self.url_patterns:
                   ^^^^^^^^^^^^^^^^^
  File "/home/lighvzkx/virtualenv/max_app/3.11/lib/python3.11/site-packages/django/utils/functional.py", line 57, in __get__
    res = instance.__dict__[self.name] = self.func(instance)
                                         ^^^^^^^^^^^^^^^^^^^
  File "/home/lighvzkx/virtualenv/max_app/3.11/lib/python3.11/site-packages/django/urls/resolvers.py", line 725, in url_patterns
    raise ImproperlyConfigured(msg.format(name=self.urlconf_name)) from e
django.core.exceptions.ImproperlyConfigured: The included URLconf '<module 'business.urls' from '/home/lighvzkx/max_app/business/urls.py'>' does not appear to have any patterns in it. If you see the 'urlpatterns' variable with valid patterns in the file then the issue is probably caused by a circular import.

During handling of the above exception, another exception occurred:

Traceback (most recent call last):
  File "/home/lighvzkx/virtualenv/max_app/3.11/lib/python3.11/site-packages/django/urls/resolvers.py", line 717, in url_patterns
    iter(patterns)
TypeError: 'module' object is not iterable

The above exception was the direct cause of the following exception:

Traceback (most recent call last):
  File "/home/lighvzkx/virtualenv/max_app/3.11/lib/python3.11/site-packages/django/core/handlers/exception.py", line 55, in inner
    response = get_response(request)
               ^^^^^^^^^^^^^^^^^^^^^
  File "/home/lighvzkx/virtualenv/max_app/3.11/lib/python3.11/site-packages/django/utils/deprecation.py", line 134, in __call__
    response = response or self.get_response(request)
                           ^^^^^^^^^^^^^^^^^^^^^^^^^^
  File "/home/lighvzkx/virtualenv/max_app/3.11/lib/python3.11/site-packages/django/core/handlers/exception.py", line 57, in inner
    response = response_for_exception(request, exc)
               ^^^^^^^^^^^^^^^^^^^^^^^^^^^^^^^^^^^^
  File "/home/lighvzkx/virtualenv/max_app/3.11/lib/python3.11/site-packages/django/core/handlers/exception.py", line 140, in response_for_exception
    response = handle_uncaught_exception(
               ^^^^^^^^^^^^^^^^^^^^^^^^^^
  File "/home/lighvzkx/virtualenv/max_app/3.11/lib/python3.11/site-packages/django/core/handlers/exception.py", line 181, in handle_uncaught_exception
    return debug.technical_500_response(request, *exc_info)
           ^^^^^^^^^^^^^^^^^^^^^^^^^^^^^^^^^^^^^^^^^^^^^^^^
  File "/home/lighvzkx/virtualenv/max_app/3.11/lib/python3.11/site-packages/django/views/debug.py", line 67, in technical_500_response
    html = reporter.get_traceback_html()
           ^^^^^^^^^^^^^^^^^^^^^^^^^^^^^
  File "/home/lighvzkx/virtualenv/max_app/3.11/lib/python3.11/site-packages/django/views/debug.py", line 410, in get_traceback_html
    c = Context(self.get_traceback_data(), use_l10n=False)
                ^^^^^^^^^^^^^^^^^^^^^^^^^
  File "/home/lighvzkx/virtualenv/max_app/3.11/lib/python3.11/site-packages/django/views/debug.py", line 393, in get_traceback_data
    c["raising_view_name"] = get_caller(self.request)
                             ^^^^^^^^^^^^^^^^^^^^^^^^
  File "/home/lighvzkx/virtualenv/max_app/3.11/lib/python3.11/site-packages/django/views/debug.py", line 100, in get_caller
    resolver_match = resolve(request.path)
                     ^^^^^^^^^^^^^^^^^^^^^
  File "/home/lighvzkx/virtualenv/max_app/3.11/lib/python3.11/site-packages/django/urls/base.py", line 24, in resolve
    return get_resolver(urlconf).resolve(path)
           ^^^^^^^^^^^^^^^^^^^^^^^^^^^^^^^^^^^
  File "/home/lighvzkx/virtualenv/max_app/3.11/lib/python3.11/site-packages/django/urls/resolvers.py", line 665, in resolve
    sub_match = pattern.resolve(new_path)
                ^^^^^^^^^^^^^^^^^^^^^^^^^
  File "/home/lighvzkx/virtualenv/max_app/3.11/lib/python3.11/site-packages/django/urls/resolvers.py", line 663, in resolve
    for pattern in self.url_patterns:
                   ^^^^^^^^^^^^^^^^^
  File "/home/lighvzkx/virtualenv/max_app/3.11/lib/python3.11/site-packages/django/utils/functional.py", line 57, in __get__
    res = instance.__dict__[self.name] = self.func(instance)
                                         ^^^^^^^^^^^^^^^^^^^
  File "/home/lighvzkx/virtualenv/max_app/3.11/lib/python3.11/site-packages/django/urls/resolvers.py", line 725, in url_patterns
    raise ImproperlyConfigured(msg.format(name=self.urlconf_name)) from e
django.core.exceptions.ImproperlyConfigured: The included URLconf '<module 'business.urls' from '/home/lighvzkx/max_app/business/urls.py'>' does not appear to have any patterns in it. If you see the 'urlpatterns' variable with valid patterns in the file then the issue is probably caused by a circular import.

During handling of the above exception, another exception occurred:

Traceback (most recent call last):
  File "/home/lighvzkx/virtualenv/max_app/3.11/lib/python3.11/site-packages/django/urls/resolvers.py", line 717, in url_patterns
    iter(patterns)
TypeError: 'module' object is not iterable

The above exception was the direct cause of the following exception:

Traceback (most recent call last):
  File "/home/lighvzkx/virtualenv/max_app/3.11/lib/python3.11/site-packages/django/core/handlers/exception.py", line 55, in inner
    response = get_response(request)
               ^^^^^^^^^^^^^^^^^^^^^
  File "/home/lighvzkx/virtualenv/max_app/3.11/lib/python3.11/site-packages/django/utils/deprecation.py", line 134, in __call__
    response = response or self.get_response(request)
                           ^^^^^^^^^^^^^^^^^^^^^^^^^^
  File "/home/lighvzkx/virtualenv/max_app/3.11/lib/python3.11/site-packages/django/core/handlers/exception.py", line 57, in inner
    response = response_for_exception(request, exc)
               ^^^^^^^^^^^^^^^^^^^^^^^^^^^^^^^^^^^^
  File "/home/lighvzkx/virtualenv/max_app/3.11/lib/python3.11/site-packages/django/core/handlers/exception.py", line 140, in response_for_exception
    response = handle_uncaught_exception(
               ^^^^^^^^^^^^^^^^^^^^^^^^^^
  File "/home/lighvzkx/virtualenv/max_app/3.11/lib/python3.11/site-packages/django/core/handlers/exception.py", line 181, in handle_uncaught_exception
    return debug.technical_500_response(request, *exc_info)
           ^^^^^^^^^^^^^^^^^^^^^^^^^^^^^^^^^^^^^^^^^^^^^^^^
  File "/home/lighvzkx/virtualenv/max_app/3.11/lib/python3.11/site-packages/django/views/debug.py", line 67, in technical_500_response
    html = reporter.get_traceback_html()
           ^^^^^^^^^^^^^^^^^^^^^^^^^^^^^
  File "/home/lighvzkx/virtualenv/max_app/3.11/lib/python3.11/site-packages/django/views/debug.py", line 410, in get_traceback_html
    c = Context(self.get_traceback_data(), use_l10n=False)
                ^^^^^^^^^^^^^^^^^^^^^^^^^
  File "/home/lighvzkx/virtualenv/max_app/3.11/lib/python3.11/site-packages/django/views/debug.py", line 393, in get_traceback_data
    c["raising_view_name"] = get_caller(self.request)
                             ^^^^^^^^^^^^^^^^^^^^^^^^
  File "/home/lighvzkx/virtualenv/max_app/3.11/lib/python3.11/site-packages/django/views/debug.py", line 100, in get_caller
    resolver_match = resolve(request.path)
                     ^^^^^^^^^^^^^^^^^^^^^
  File "/home/lighvzkx/virtualenv/max_app/3.11/lib/python3.11/site-packages/django/urls/base.py", line 24, in resolve
    return get_resolver(urlconf).resolve(path)
           ^^^^^^^^^^^^^^^^^^^^^^^^^^^^^^^^^^^
  File "/home/lighvzkx/virtualenv/max_app/3.11/lib/python3.11/site-packages/django/urls/resolvers.py", line 665, in resolve
    sub_match = pattern.resolve(new_path)
                ^^^^^^^^^^^^^^^^^^^^^^^^^
  File "/home/lighvzkx/virtualenv/max_app/3.11/lib/python3.11/site-packages/django/urls/resolvers.py", line 663, in resolve
    for pattern in self.url_patterns:
                   ^^^^^^^^^^^^^^^^^
  File "/home/lighvzkx/virtualenv/max_app/3.11/lib/python3.11/site-packages/django/utils/functional.py", line 57, in __get__
    res = instance.__dict__[self.name] = self.func(instance)
                                         ^^^^^^^^^^^^^^^^^^^
  File "/home/lighvzkx/virtualenv/max_app/3.11/lib/python3.11/site-packages/django/urls/resolvers.py", line 725, in url_patterns
    raise ImproperlyConfigured(msg.format(name=self.urlconf_name)) from e
django.core.exceptions.ImproperlyConfigured: The included URLconf '<module 'business.urls' from '/home/lighvzkx/max_app/business/urls.py'>' does not appear to have any patterns in it. If you see the 'urlpatterns' variable with valid patterns in the file then the issue is probably caused by a circular import.

During handling of the above exception, another exception occurred:

Traceback (most recent call last):
  File "/home/lighvzkx/virtualenv/max_app/3.11/lib/python3.11/site-packages/django/urls/resolvers.py", line 717, in url_patterns
    iter(patterns)
TypeError: 'module' object is not iterable

The above exception was the direct cause of the following exception:

Traceback (most recent call last):
  File "/home/lighvzkx/virtualenv/max_app/3.11/lib/python3.11/site-packages/django/core/handlers/wsgi.py", line 124, in __call__
    response = self.get_response(request)
               ^^^^^^^^^^^^^^^^^^^^^^^^^^
  File "/home/lighvzkx/virtualenv/max_app/3.11/lib/python3.11/site-packages/django/core/handlers/base.py", line 140, in get_response
    response = self._middleware_chain(request)
               ^^^^^^^^^^^^^^^^^^^^^^^^^^^^^^^
  File "/home/lighvzkx/virtualenv/max_app/3.11/lib/python3.11/site-packages/django/core/handlers/exception.py", line 57, in inner
    response = response_for_exception(request, exc)
               ^^^^^^^^^^^^^^^^^^^^^^^^^^^^^^^^^^^^
  File "/home/lighvzkx/virtualenv/max_app/3.11/lib/python3.11/site-packages/django/core/handlers/exception.py", line 140, in response_for_exception
    response = handle_uncaught_exception(
               ^^^^^^^^^^^^^^^^^^^^^^^^^^
  File "/home/lighvzkx/virtualenv/max_app/3.11/lib/python3.11/site-packages/django/core/handlers/exception.py", line 181, in handle_uncaught_exception
    return debug.technical_500_response(request, *exc_info)
           ^^^^^^^^^^^^^^^^^^^^^^^^^^^^^^^^^^^^^^^^^^^^^^^^
  File "/home/lighvzkx/virtualenv/max_app/3.11/lib/python3.11/site-packages/django/views/debug.py", line 67, in technical_500_response
    html = reporter.get_traceback_html()
           ^^^^^^^^^^^^^^^^^^^^^^^^^^^^^
  File "/home/lighvzkx/virtualenv/max_app/3.11/lib/python3.11/site-packages/django/views/debug.py", line 410, in get_traceback_html
    c = Context(self.get_traceback_data(), use_l10n=False)
                ^^^^^^^^^^^^^^^^^^^^^^^^^
  File "/home/lighvzkx/virtualenv/max_app/3.11/lib/python3.11/site-packages/django/views/debug.py", line 393, in get_traceback_data
    c["raising_view_name"] = get_caller(self.request)
                             ^^^^^^^^^^^^^^^^^^^^^^^^
  File "/home/lighvzkx/virtualenv/max_app/3.11/lib/python3.11/site-packages/django/views/debug.py", line 100, in get_caller
    resolver_match = resolve(request.path)
                     ^^^^^^^^^^^^^^^^^^^^^
  File "/home/lighvzkx/virtualenv/max_app/3.11/lib/python3.11/site-packages/django/urls/base.py", line 24, in resolve
    return get_resolver(urlconf).resolve(path)
           ^^^^^^^^^^^^^^^^^^^^^^^^^^^^^^^^^^^
  File "/home/lighvzkx/virtualenv/max_app/3.11/lib/python3.11/site-packages/django/urls/resolvers.py", line 665, in resolve
    sub_match = pattern.resolve(new_path)
                ^^^^^^^^^^^^^^^^^^^^^^^^^
  File "/home/lighvzkx/virtualenv/max_app/3.11/lib/python3.11/site-packages/django/urls/resolvers.py", line 663, in resolve
    for pattern in self.url_patterns:
                   ^^^^^^^^^^^^^^^^^
  File "/home/lighvzkx/virtualenv/max_app/3.11/lib/python3.11/site-packages/django/utils/functional.py", line 57, in __get__
    res = instance.__dict__[self.name] = self.func(instance)
                                         ^^^^^^^^^^^^^^^^^^^
  File "/home/lighvzkx/virtualenv/max_app/3.11/lib/python3.11/site-packages/django/urls/resolvers.py", line 725, in url_patterns
    raise ImproperlyConfigured(msg.format(name=self.urlconf_name)) from e
django.core.exceptions.ImproperlyConfigured: The included URLconf '<module 'business.urls' from '/home/lighvzkx/max_app/business/urls.py'>' does not appear to have any patterns in it. If you see the 'urlpatterns' variable with valid patterns in the file then the issue is probably caused by a circular import.
